Workbook

Sheet Asset Allocation
A1: Asset | B1: Mumbai | C1: Germany | D1: Manila | E1: San Francisco | F1: Calgary | G1: Gulf of Mexico | H1: Tokyo | I1: Caribbean Islands | J1: Texas | K1: Asset Life (in Yrs) | L1: Mumbai | M1: Germany | N1: Manila | O1: San Francisco | P1: Calgary | Q1: Gulf of Mexico | R1: Tokyo | S1: Caribbean Islands | T1: Texas
A2: Heavy Machinery | B2: 200000 | C2: 300000 | K2: 10 | L2: A1 | M2: A16 | N2: A31 | O2: A46 | P2: A61 | Q2: A76 | R2: A91 | S2: A106 | T2: A121
A3: Heat Exchanger | B3: 200000 | E3: 600000 | K3: 5 | L3: A2 | M3: A17 | N3: A32 | O3: A47 | P3: A62 | Q3: A77 | R3: A92 | S3: A107 | T3: A122
A4: Pipelines | D4: 400000 | G4: 400000 | H4: 400000 | K4: 10 | L4: A3 | M4: A18 | N4: A33 | O4: A48 | P4: A63 | Q4: A78 | R4: A93 | S4: A108 | T4: A123
A5: Property (Office Locations) | B5: 700000 | C5: 500000 | D5: 400000 | E5: 800000 | F5: 1000000 | G5: 500000 | H5: 300000 | I5: 400000 | J5: 1200000 | K5: 10 | L5: A4 | M5: A19 | N5: A34 | O5: A49 | P5: A64 | Q5: A79 | R5: A94 | S5: A109 | T5: A124
A6: Manufacturing Plants | C6: 500000 | J6: 300000 | K6: 10 | L6: A5 | M6: A20 | N6: A35 | O6: A50 | P6: A65 | Q6: A80 | R6: A95 | S6: A110 | T6: A125
A7: Warehouse & Cold Storage | B7: 400000 | D7: 300000 | G7: 200000 | K7: 5 | L7: A6 | M7: A21 | N7: A36 | O7: A51 | P7: A66 | Q7: A81 | R7: A96 | S7: A111 | T7: A126
A8: Hotels & Resorts | B8: 800000 | C8: 1000000 | F8: 1100000 | J8: 1000000 | K8: 10 | L8: A7 | M8: A22 | N8: A37 | O8: A52 | P8: A67 | Q8: A82 | R8: A97 | S8: A112 | T8: A127
A9: Supermarkets & Malls | B9: 300000 | C9: 300000 | D9: 500000 | E9: 500000 | F9: 300000 | G9: 300000 | H9: 300000 | I9: 600000 | J9: 300000 | K9: 5 | L9: A8 | M9: A23 | N9: A38 | O9: A53 | P9: A68 | Q9: A83 | R9: A98 | S9: A113 | T9: A128
A10: Mines | B10: 300000 | E10: 300000 | F10: 300000 | H10: 300000 | K10: 10 | L10: A9 | M10: A24 | N10: A39 | O10: A54 | P10: A69 | Q10: A84 | R10: A99 | S10: A114 | T10: A129
A11: Power Plants | B11: 400000 | C11: 300000 | D11: 300000 | E11: 500000 | K11: 5 | L11: A10 | M11: A25 | N11: A40 | O11: A55 | P11: A70 | Q11: A85 | R11: A100 | S11: A115 | T11: A130
A12: Oil Refineries | B12: 1000000 | F12: 1000000 | J12: 1000000 | K12: 10 | L12: A11 | M12: A26 | N12: A41 | O12: A56 | P12: A71 | Q12: A86 | R12: A101 | S12: A116 | T12: A131
A13: Telecom Towers | B13: 500000 | F13: 500000 | J13: 500000 | K13: 4 | L13: A12 | M13: A27 | N13: A42 | O13: A57 | P13: A72 | Q13: A87 | R13: A102 | S13: A117 | T13: A132
A14: Aircrafts | B14: 200000 | C14: 400000 | D14: 500000 | E14: 200000 | F14: 200000 | G14: 500000 | H14: 200000 | I14: 600000 | J14: 200000 | K14: 5 | L14: A13 | M14: A28 | N14: A43 | O14: A58 | P14: A73 | Q14: A88 | R14: A103 | S14: A118 | T14: A133
A15: Ships & Cargo | B15: 300000 | K15: 5 | L15: A14 | M15: A29 | N15: A44 | O15: A59 | P15: A74 | Q15: A89 | R15: A104 | S15: A119 | T15: A134
A16: Fleets & Cars | B16: 200000 | C16: 200000 | D16: 300000 | E16: 400000 | F16: 200000 | G16: 600000 | H16: 400000 | I16: 200000 | J16: 200000 | K16: 4 | L16: A15 | M16: A30 | N16: A45 | O16: A60 | P16: A75 | Q16: A90 | R16: A105 | S16: A120 | T16: A135

Sheet Peril Sheet
A1: Policy Code | B1: Policy Desciption (Perils covered) | C1: Asset | D1: Asset Name
A2: P1 | B2: ='Risk Master'!C2&"-"&'Risk Master'!D2 -> Flood-Mumbai | C2: ='Risk Master'!F2 -> A1 | D2: =VLOOKUP(C2,'Asset Master'!A:B,2,FALSE) -> Heavy Machinery-Mumbai
A3: P2 | B3: ='Risk Master'!C3&"-"&'Risk Master'!D3 -> Earthquake-Mumbai | C3: ='Risk Master'!F3 -> A1 | D3: =VLOOKUP(C3,'Asset Master'!A:B,2,FALSE) -> Heavy Machinery-Mumbai
A4: P3 | B4: ='Risk Master'!C4&"-"&'Risk Master'!D4 -> Fire-Mumbai | C4: ='Risk Master'!F4 -> A1 | D4: =VLOOKUP(C4,'Asset Master'!A:B,2,FALSE) -> Heavy Machinery-Mumbai
A5: P4 | B5: ='Risk Master'!C5&"-"&'Risk Master'!D5 -> Typhoon-Mumbai | C5: ='Risk Master'!F5 -> A1 | D5: =VLOOKUP(C5,'Asset Master'!A:B,2,FALSE) -> Heavy Machinery-Mumbai
A6: P5 | B6: ='Risk Master'!C6&"-"&'Risk Master'!D6 -> Thunderstorms, Tornados & Hail-Mumbai | C6: ='Risk Master'!F6 -> A1 | D6: =VLOOKUP(C6,'Asset Master'!A:B,2,FALSE) -> Heavy Machinery-Mumbai
A7: P6 | B7: ='Risk Master'!C7&"-"&'Risk Master'!D7 -> Tsunami-Mumbai | C7: ='Risk Master'!F7 -> A1 | D7: =VLOOKUP(C7,'Asset Master'!A:B,2,FALSE) -> Heavy Machinery-Mumbai
A8: P7 | B8: ='Risk Master'!C8&"-"&'Risk Master'!D8 -> Flood-Mumbai | C8: ='Risk Master'!F8 -> A2 | D8: =VLOOKUP(C8,'Asset Master'!A:B,2,FALSE) -> Heat Exchanger-Mumbai
A9: P8 | B9: ='Risk Master'!C9&"-"&'Risk Master'!D9 -> Earthquake-Mumbai | C9: ='Risk Master'!F9 -> A2 | D9: =VLOOKUP(C9,'Asset Master'!A:B,2,FALSE) -> Heat Exchanger-Mumbai
A10: P9 | B10: ='Risk Master'!C10&"-"&'Risk Master'!D10 -> Fire-Mumbai | C10: ='Risk Master'!F10 -> A2 | D10: =VLOOKUP(C10,'Asset Master'!A:B,2,FALSE) -> Heat Exchanger-Mumbai
A11: P10 | B11: ='Risk Master'!C11&"-"&'Risk Master'!D11 -> Typhoon-Mumbai | C11: ='Risk Master'!F11 -> A2 | D11: =VLOOKUP(C11,'Asset Master'!A:B,2,FALSE) -> Heat Exchanger-Mumbai
A12: P11 | B12: ='Risk Master'!C12&"-"&'Risk Master'!D12 -> Thunderstorms, Tornados & Hail-Mumbai | C12: ='Risk Master'!F12 -> A4 | D12: =VLOOKUP(C12,'Asset Master'!A:B,2,FALSE) -> Property (Office Locations)-Mumbai
A13: P12 | B13: ='Risk Master'!C13&"-"&'Risk Master'!D13 -> Tsunami-Mumbai | C13: ='Risk Master'!F13 -> A4 | D13: =VLOOKUP(C13,'Asset Master'!A:B,2,FALSE) -> Property (Office Locations)-Mumbai
... A183: P182 | B183: ='Risk Master'!C183&"-"&'Risk Master'!D183 -> Hurricane-Typhoon -Texas | C183: ='Risk Master'!F183 -> A135 | D183: =VLOOKUP(C183,'Asset Master'!A:B,2,FALSE) -> Fleets & Cars-Texas

Sheet Probabilty Distribution
A1: Risk Events | B1: Probability | C1: 1914 | D1: 1915 | E1: 1916 | F1: 1917 | G1: 1918 | H1: 1919 | I1: 1920 | J1: 1921 | K1: 1922 | L1: 1923 | M1: 1924 | N1: 1925 | O1: 1926 | P1: 1927 | Q1: 1928 | R1: 1929 | S1: 1930 | T1: 1931 | U1: 1932 | V1: 1933 | W1: 1934 | X1: 1935 | Y1: 1936 | Z1: 1937 | AA1: 1938 | AB1: 1939 | AC1: 1940 | AD1: 1941 | AE1: 1942 | AF1: 1943 | AG1: 1944 | AH1: 1945 | AI1: 1946 | AJ1: 1947 | AK1: 1948 | AL1: 1949 | AM1: 1950 | AN1: 1951 | AO1: 1952 | AP1: 1953 | AQ1: 1954 | AR1: 1955 | AS1: 1956 | AT1: 1957 | AU1: 1958 | AV1: 1959 | AW1: 1960 | AX1: 1961 | AY1: 1962 | AZ1: 1963 | BA1: 1964 | BB1: 1965 | BC1: 1966 | BD1: 1967 | BE1: 1968 | BF1: 1969 | BG1: 1970 | BH1: 1971 | BI1: 1972 | BJ1: 1973 | BK1: 1974 | BL1: 1975 | BM1: 1976 | BN1: 1977 | BO1: 1978 | BP1: 1979 | BQ1: 1980 | BR1: 1981 | BS1: 1982 | BT1: 1983 | BU1: 1984 | BV1: 1985 | BW1: 1986 | BX1: 1987 | BY1: 1988 | BZ1: 1989 | CA1: 1990 | CB1: 1991 | CC1: 1992 | CD1: 1993 | CE1: 1994 | CF1: 1995 | CG1: 1996 | CH1: 1997 | CI1: 1998 | CJ1: 1999 | CK1: 2000 | CL1: 2001 | CM1: 2002 | CN1: 2003 | CO1: 2004 | CP1: 2005 | CQ1: 2006 | CR1: 2007 | CS1: 2008 | CT1: 2009 | CU1: 2010 | CV1: 2011 | CW1: 2012 | CX1: 2013
A2: Flood-Mumbai | B2: 0.17 | C2: 1 | D2: 0 | E2: 0 | F2: 0 | G2: 0 | H2: 0 | I2: 0 | J2: 0 | K2: 1 | L2: 0 | M2: 0 | N2: 0 | O2: 1 | P2: 0 | Q2: 0 | R2: 0 | S2: 0 | T2: 0 | U2: 1 | V2: 0 | W2: 0 | X2: 0 | Y2: 0 | Z2: 0 | AA2: 0 | AB2: 0 | AC2: 0 | AD2: 0 | AE2: 0 | AF2: 0 | AG2: 0 | AH2: 0 | AI2: 0 | AJ2: 0 | AK2: 0 | AL2: 0 | AM2: 0 | AN2: 0 | AO2: 0 | AP2: 0 | AQ2: 0 | AR2: 0 | AS2: 0 | AT2: 1 | AU2: 0 | AV2: 0 | AW2: 0 | AX2: 1 | AY2: 0 | AZ2: 0 | BA2: 1 | BB2: 0 | BC2: 0 | BD2: 0 | BE2: 1 | BF2: 0 | BG2: 0 | BH2: 0 | BI2: 1 | BJ2: 0 | BK2: 0 | BL2: 0 | BM2: 0 | BN2: 0 | BO2: 1 | BP2: 0 | BQ2: 0 | BR2: 0 | BS2: 0 | BT2: 0 | BU2: 0 | BV2: 1 | BW2: 1 | BX2: 0 | BY2: 0 | BZ2: 1 | CA2: 0 | CB2: 0 | CC2: 0 | CD2: 1 | CE2: 0 | CF2: 0 | CG2: 0 | CH2: 0 | CI2: 0 | CJ2: 1 | CK2: 0 | CL2: 0 | CM2: 0 | CN2: 0 | CO2: 0 | CP2: 0 | CQ2: 0 | CR2: 0 | CS2: 0 | CT2: 1 | CU2: 0 | CV2: 0 | CW2: 1 | CX2: 0
A3: Earthquake-Mumbai | B3: 0.2 | C3: 0 | D3: 0 | E3: 0 | F3: 1 | G3: 0 | H3: 0 | I3: 0 | J3: 0 | K3: 0 | L3: 1 | M3: 1 | N3: 1 | O3: 0 | P3: 0 | Q3: 0 | R3: 0 | S3: 0 | T3: 1 | U3: 1 | V3: 0 | W3: 1 | X3: 0 | Y3: 0 | Z3: 1 | AA3: 0 | AB3: 0 | AC3: 0 | AD3: 0 | AE3: 0 | AF3: 1 | AG3: 0 | AH3: 0 | AI3: 0 | AJ3: 0 | AK3: 1 | AL3: 0 | AM3: 0 | AN3: 0 | AO3: 1 | AP3: 1 | AQ3: 0 | AR3: 0 | AS3: 0 | AT3: 0 | AU3: 1 | AV3: 0 | AW3: 1 | AX3: 1 | AY3: 0 | AZ3: 1 | BA3: 0 | BB3: 1 | BC3: 0 | BD3: 0 | BE3: 0 | BF3: 0 | BG3: 0 | BH3: 0 | BI3: 0 | BJ3: 0 | BK3: 0 | BL3: 0 | BM3: 0 | BN3: 0 | BO3: 0 | BP3: 1 | BQ3: 0 | BR3: 0 | BS3: 0 | BT3: 0 | BU3: 0 | BV3: 0 | BW3: 0 | BX3: 0 | BY3: 0 | BZ3: 0 | CA3: 1 | CB3: 0 | CC3: 0 | CD3: 0 | CE3: 1 | CF3: 0 | CG3: 1 | CH3: 1 | CI3: 0 | CJ3: 1 | CK3: 0 | CL3: 1 | CM3: 0 | CN3: 0 | CO3: 0 | CP3: 0 | CQ3: 0 | CR3: 0 | CS3: 0 | CT3: 0 | CU3: 0 | CV3: 0 | CW3: 0 | CX3: 1
A4: Fire-Mumbai | B4: 0.2 | C4: 0 | D4: 0 | E4: 0 | F4: 1 | G4: 0 | H4: 0 | I4: 1 | J4: 0 | K4: 0 | L4: 0 | M4: 0 | N4: 0 | O4: 0 | P4: 0 | Q4: 0 | R4: 0 | S4: 0 | T4: 0 | U4: 0 | V4: 1 | W4: 1 | X4: 1 | Y4: 0 | Z4: 0 | AA4: 0 | AB4: 0 | AC4: 0 | AD4: 0 | AE4: 0 | AF4: 0 | AG4: 0 | AH4: 0 | AI4: 0 | AJ4: 0 | AK4: 0 | AL4: 1 | AM4: 0 | AN4: 1 | AO4: 0 | AP4: 1 | AQ4: 0 | AR4: 0 | AS4: 0 | AT4: 0 | AU4: 0 | AV4: 1 | AW4: 0 | AX4: 0 | AY4: 0 | AZ4: 0 | BA4: 0 | BB4: 1 | BC4: 1 | BD4: 0 | BE4: 0 | BF4: 0 | BG4: 0 | BH4: 0 | BI4: 0 | BJ4: 0 | BK4: 0 | BL4: 0 | BM4: 0 | BN4: 1 | BO4: 0 | BP4: 0 | BQ4: 1 | BR4: 1 | BS4: 0 | BT4: 1 | BU4: 0 | BV4: 1 | BW4: 1 | BX4: 0 | BY4: 0 | BZ4: 0 | CA4: 0 | CB4: 0 | CC4: 0 | CD4: 0 | CE4: 0 | CF4: 0 | CG4: 0 | CH4: 0 | CI4: 0 | CJ4: 0 | CK4: 0 | CL4: 0 | CM4: 0 | CN4: 0 | CO4: 1 | CP4: 1 | CQ4: 0 | CR4: 0 | CS4: 0 | CT4: 1 | CU4: 0 | CV4: 0 | CW4: 0 | CX4: 0
A5: Terror Attack-Mumbai | C5: 0 | D5: 0 | E5: 0 | F5: 0 | G5: 0 | H5: 0 | I5: 0 | J5: 1 | K5: 0 | L5: 0 | M5: 0 | N5: 0 | O5: 0 | P5: 0 | Q5: 0 | R5: 0 | S5: 0 | T5: 0 | U5: 0 | V5: 0 | W5: 0 | X5: 0 | Y5: 0 | Z5: 0 | AA5: 0 | AB5: 0 | AC5: 0 | AD5: 0 | AE5: 0 | AF5: 0 | AG5: 0 | AH5: 0 | AI5: 0 | AJ5: 0 | AK5: 0 | AL5: 0 | AM5: 0 | AN5: 0 | AO5: 0 | AP5: 0 | AQ5: 0 | AR5: 0 | AS5: 0 | AT5: 0 | AU5: 0 | AV5: 0 | AW5: 0 | AX5: 0 | AY5: 0 | AZ5: 0 | BA5: 0 | BB5: 0 | BC5: 0 | BD5: 0 | BE5: 0 | BF5: 0 | BG5: 0 | BH5: 0 | BI5: 0 | BJ5: 0 | BK5: 0 | BL5: 0 | BM5: 0 | BN5: 0 | BO5: 0 | BP5: 0 | BQ5: 0 | BR5: 0 | BS5: 0 | BT5: 0 | BU5: 0 | BV5: 0 | BW5: 0 | BX5: 0 | BY5: 0 | BZ5: 0 | CA5: 0 | CB5: 0 | CC5: 0 | CD5: 0 | CE5: 0 | CF5: 0 | CG5: 0 | CH5: 0 | CI5: 0 | CJ5: 0 | CK5: 0 | CL5: 1 | CM5: 0 | CN5: 0 | CO5: 0 | CP5: 0 | CQ5: 0 | CR5: 0 | CS5: 0 | CT5: 0 | CU5: 0 | CV5: 1 | CW5: 0 | CX5: 1
A6: Typhoon-Mumbai | B6: 0.3 | C6: 0 | D6: 0 | E6: 1 | F6: 0 | G6: 0 | H6: 1 | I6: 0 | J6: 0 | K6: 0 | L6: 0 | M6: 1 | N6: 0 | O6: 0 | P6: 0 | Q6: 0 | R6: 0 | S6: 0 | T6: 0 | U6: 0 | V6: 0 | W6: 1 | X6: 0 | Y6: 0 | Z6: 0 | AA6: 1 | AB6: 1 | AC6: 1 | AD6: 0 | AE6: 0 | AF6: 0 | AG6: 0 | AH6: 0 | AI6: 0 | AJ6: 0 | AK6: 0 | AL6: 0 | AM6: 0 | AN6: 0 | AO6: 1 | AP6: 0 | AQ6: 0 | AR6: 0 | AS6: 0 | AT6: 1 | AU6: 0 | AV6: 1 | AW6: 1 | AX6: 0 | AY6: 0 | AZ6: 1 | BA6: 1 | BB6: 0 | BC6: 1 | BD6: 0 | BE6: 0 | BF6: 0 | BG6: 0 | BH6: 0 | BI6: 0 | BJ6: 0 | BK6: 0 | BL6: 0 | BM6: 0 | BN6: 1 | BO6: 0 | BP6: 0 | BQ6: 0 | BR6: 0 | BS6: 0 | BT6: 0 | BU6: 1 | BV6: 0 | BW6: 1 | BX6: 1 | BY6: 0 | BZ6: 0 | CA6: 1 | CB6: 0 | CC6: 0 | CD6: 0 | CE6: 1 | CF6: 1 | CG6: 0 | CH6: 0 | CI6: 1 | CJ6: 0 | CK6: 0 | CL6: 0 | CM6: 0 | CN6: 0 | CO6: 1 | CP6: 0 | CQ6: 1 | CR6: 0 | CS6: 1 | CT6: 0 | CU6: 1 | CV6: 0 | CW6: 0 | CX6: 0
A7: Thunderstorms, Tornados & Hail-Mumbai | B7: 0.15 | C7: 0 | D7: 0 | E7: 0 | F7: 0 | G7: 0 | H7: 0 | I7: 1 | J7: 0 | K7: 0 | L7: 0 | M7: 1 | N7: 0 | O7: 0 | P7: 0 | Q7: 0 | R7: 0 | S7: 0 | T7: 0 | U7: 1 | V7: 0 | W7: 0 | X7: 0 | Y7: 0 | Z7: 0 | AA7: 0 | AB7: 0 | AC7: 0 | AD7: 0 | AE7: 0 | AF7: 0 | AG7: 0 | AH7: 0 | AI7: 1 | AJ7: 0 | AK7: 0 | AL7: 0 | AM7: 1 | AN7: 1 | AO7: 0 | AP7: 0 | AQ7: 0 | AR7: 1 | AS7: 1 | AT7: 0 | AU7: 0 | AV7: 0 | AW7: 0 | AX7: 1 | AY7: 0 | AZ7: 0 | BA7: 0 | BB7: 0 | BC7: 0 | BD7: 0 | BE7: 0 | BF7: 0 | BG7: 0 | BH7: 0 | BI7: 0 | BJ7: 0 | BK7: 1 | BL7: 0 | BM7: 0 | BN7: 0 | BO7: 0 | BP7: 0 | BQ7: 0 | BR7: 0 | BS7: 0 | BT7: 0 | BU7: 0 | BV7: 0 | BW7: 0 | BX7: 0 | BY7: 0 | BZ7: 0 | CA7: 0 | CB7: 0 | CC7: 0 | CD7: 0 | CE7: 0 | CF7: 0 | CG7: 0 | CH7: 0 | CI7: 0 | CJ7: 0 | CK7: 1 | CL7: 0 | CM7: 0 | CN7: 1 | CO7: 0 | CP7: 0 | CQ7: 0 | CR7: 0 | CS7: 0 | CT7: 0 | CU7: 0 | CV7: 1 | CW7: 0 | CX7: 0
A8: Tsunami-Mumbai | B8: 0.14 | C8: 0 | D8: 0 | E8: 0 | F8: 0 | G8: 0 | H8: 1 | I8: 0 | J8: 1 | K8: 1 | L8: 0 | M8: 0 | N8: 1 | O8: 0 | P8: 0 | Q8: 0 | R8: 0 | S8: 0 | T8: 0 | U8: 0 | V8: 0 | W8: 0 | X8: 1 | Y8: 0 | Z8: 0 | AA8: 1 | AB8: 0 | AC8: 0 | AD8: 0 | AE8: 0 | AF8: 0 | AG8: 0 | AH8: 0 | AI8: 1 | AJ8: 0 | AK8: 0 | AL8: 0 | AM8: 0 | AN8: 0 | AO8: 0 | AP8: 0 | AQ8: 0 | AR8: 0 | AS8: 0 | AT8: 0 | AU8: 0 | AV8: 0 | AW8: 0 | AX8: 0 | AY8: 0 | AZ8: 0 | BA8: 0 | BB8: 0 | BC8: 0 | BD8: 0 | BE8: 0 | BF8: 0 | BG8: 0 | BH8: 1 | BI8: 0 | BJ8: 0 | BK8: 0 | BL8: 0 | BM8: 1 | BN8: 0 | BO8: 0 | BP8: 0 | BQ8: 0 | BR8: 0 | BS8: 0 | BT8: 0 | BU8: 1 | BV8: 0 | BW8: 0 | BX8: 0 | BY8: 0 | BZ8: 0 | CA8: 0 | CB8: 1 | CC8: 1 | CD8: 0 | CE8: 0 | CF8: 0 | CG8: 0 | CH8: 0 | CI8: 0 | CJ8: 0 | CK8: 0 | CL8: 1 | CM8: 1 | CN8: 0 | CO8: 0 | CP8: 0 | CQ8: 0 | CR8: 0 | CS8: 0 | CT8: 0 | CU8: 0 | CV8: 1 | CW8: 0 | CX8: 0
A9: Hurricane-Typhoon -Germany | B9: 0.15 | C9: 0 | D9: 0 | E9: 1 | F9: 0 | G9: 0 | H9: 0 | I9: 0 | J9: 1 | K9: 0 | L9: 0 | M9: 0 | N9: 0 | O9: 1 | P9: 0 | Q9: 0 | R9: 0 | S9: 0 | T9: 0 | U9: 0 | V9: 0 | W9: 0 | X9: 0 | Y9: 0 | Z9: 0 | AA9: 0 | AB9: 0 | AC9: 0 | AD9: 0 | AE9: 0 | AF9: 1 | AG9: 0 | AH9: 0 | AI9: 1 | AJ9: 1 | AK9: 0 | AL9: 1 | AM9: 0 | AN9: 0 | AO9: 0 | AP9: 0 | AQ9: 1 | AR9: 0 | AS9: 0 | AT9: 0 | AU9: 0 | AV9: 0 | AW9: 0 | AX9: 1 | AY9: 0 | AZ9: 0 | BA9: 0 | BB9: 0 | BC9: 0 | BD9: 0 | BE9: 0 | BF9: 0 | BG9: 0 | BH9: 0 | BI9: 0 | BJ9: 1 | BK9: 0 | BL9: 0 | BM9: 0 | BN9: 0 | BO9: 0 | BP9: 0 | BQ9: 0 | BR9: 0 | BS9: 0 | BT9: 0 | BU9: 0 | BV9: 0 | BW9: 0 | BX9: 0 | BY9: 0 | BZ9: 0 | CA9: 0 | CB9: 1 | CC9: 0 | CD9: 0 | CE9: 0 | CF9: 0 | CG9: 0 | CH9: 0 | CI9: 0 | CJ9: 0 | CK9: 0 | CL9: 0 | CM9: 1 | CN9: 1 | CO9: 0 | CP9: 0 | CQ9: 0 | CR9: 0 | CS9: 0 | CT9: 0 | CU9: 1 | CV9: 0 | CW9: 0 | CX9: 0
A10: Earthquake-Germany | B10: 0.1 | C10: 0 | D10: 0 | E10: 0 | F10: 0 | G10: 0 | H10: 0 | I10: 0 | J10: 0 | K10: 0 | L10: 0 | M10: 0 | N10: 0 | O10: 0 | P10: 1 | Q10: 1 | R10: 0 | S10: 0 | T10: 0 | U10: 0 | V10: 0 | W10: 0 | X10: 0 | Y10: 0 | Z10: 0 | AA10: 0 | AB10: 0 | AC10: 0 | AD10: 1 | AE10: 0 | AF10: 1 | AG10: 0 | AH10: 0 | AI10: 0 | AJ10: 0 | AK10: 0 | AL10: 0 | AM10: 0 | AN10: 0 | AO10: 0 | AP10: 0 | AQ10: 0 | AR10: 0 | AS10: 0 | AT10: 0 | AU10: 0 | AV10: 0 | AW10: 0 | AX10: 0 | AY10: 0 | AZ10: 0 | BA10: 1 | BB10: 0 | BC10: 0 | BD10: 0 | BE10: 0 | BF10: 0 | BG10: 0 | BH10: 0 | BI10: 1 | BJ10: 0 | BK10: 0 | BL10: 0 | BM10: 0 | BN10: 0 | BO10: 1 | BP10: 0 | BQ10: 0 | BR10: 0 | BS10: 0 | BT10: 0 | BU10: 1 | BV10: 0 | BW10: 0 | BX10: 0 | BY10: 0 | BZ10: 0 | CA10: 0 | CB10: 0 | CC10: 0 | CD10: 0 | CE10: 0 | CF10: 0 | CG10: 0 | CH10: 0 | CI10: 0 | CJ10: 0 | CK10: 0 | CL10: 0 | CM10: 0 | CN10: 0 | CO10: 0 | CP10: 0 | CQ10: 0 | CR10: 0 | CS10: 0 | CT10: 0 | CU10: 0 | CV10: 0 | CW10: 0 | CX10: 0
A11: Fire-Germany | B11: 0.25 | C11: 0 | D11: 0 | E11: 0 | F11: 0 | G11: 0 | H11: 0 | I11: 0 | J11: 1 | K11: 0 | L11: 0 | M11: 1 | N11: 0 | O11: 0 | P11: 0 | Q11: 1 | R11: 0 | S11: 0 | T11: 0 | U11: 0 | V11: 0 | W11: 0 | X11: 0 | Y11: 0 | Z11: 0 | AA11: 0 | AB11: 0 | AC11: 0 | AD11: 0 | AE11: 0 | AF11: 1 | AG11: 0 | AH11: 0 | AI11: 0 | AJ11: 0 | AK11: 0 | AL11: 0 | AM11: 0 | AN11: 1 | AO11: 0 | AP11: 0 | AQ11: 0 | AR11: 1 | AS11: 0 | AT11: 0 | AU11: 0 | AV11: 0 | AW11: 0 | AX11: 1 | AY11: 0 | AZ11: 0 | BA11: 0 | BB11: 1 | BC11: 0 | BD11: 0 | BE11: 0 | BF11: 0 | BG11: 0 | BH11: 0 | BI11: 0 | BJ11: 0 | BK11: 0 | BL11: 1 | BM11: 1 | BN11: 0 | BO11: 0 | BP11: 0 | BQ11: 0 | BR11: 0 | BS11: 0 | BT11: 0 | BU11: 0 | BV11: 1 | BW11: 0 | BX11: 0 | BY11: 0 | BZ11: 1 | CA11: 0 | CB11: 1 | CC11: 1 | CD11: 0 | CE11: 0 | CF11: 1 | CG11: 0 | CH11: 0 | CI11: 0 | CJ11: 1 | CK11: 0 | CL11: 0 | CM11: 0 | CN11: 0 | CO11: 1 | CP11: 0 | CQ11: 0 | CR11: 1 | CS11: 0 | CT11: 1 | CU11: 1 | CV11: 0 | CW11: 1 | CX11: 1
A12: Thunderstorms, Tornados & Hail-Germany | B12: 0.3 | C12: 1 | D12: 0 | E12: 0 | F12: 0 | G12: 0 | H12: 0 | I12: 0 | J12: 1 | K12: 1 | L12: 0 | M12: 1 | N12: 0 | O12: 1 | P12: 0 | Q12: 0 | R12: 0 | S12: 1 | T12: 0 | U12: 0 | V12: 0 | W12: 0 | X12: 0 | Y12: 1 | Z12: 0 | AA12: 0 | AB12: 0 | AC12: 0 | AD12: 1 | AE12: 0 | AF12: 0 | AG12: 0 | AH12: 1 | AI12: 0 | AJ12: 1 | AK12: 0 | AL12: 0 | AM12: 0 | AN12: 0 | AO12: 1 | AP12: 1 | AQ12: 1 | AR12: 1 | AS12: 0 | AT12: 0 | AU12: 0 | AV12: 1 | AW12: 0 | AX12: 1 | AY12: 1 | AZ12: 0 | BA12: 1 | BB12: 1 | BC12: 1 | BD12: 1 | BE12: 0 | BF12: 0 | BG12: 0 | BH12: 1 | BI12: 0 | BJ12: 0 | BK12: 0 | BL12: 0 | BM12: 0 | BN12: 0 | BO12: 1 | BP12: 1 | BQ12: 1 | BR12: 1 | BS12: 0 | BT12: 0 | BU12: 1 | BV12: 1 | BW12: 0 | BX12: 0 | BY12: 0 | BZ12: 0 | CA12: 0 | CB12: 1 | CC12: 0 | CD12: 1 | CE12: 0 | CF12: 0 | CG12: 0 | CH12: 0 | CI12: 0 | CJ12: 0 | CK12: 0 | CL12: 1 | CM12: 0 | CN12: 1 | CO12: 0 | CP12: 0 | CQ12: 0 | CR12: 1 | CS12: 0 | CT12: 1 | CU12: 1 | CV12: 1 | CW12: 0 | CX12: 0
A13: Hurricane-Typhoon -Manila | B13: 0.2 | C13: 0 | D13: 1 | E13: 0 | F13: 1 | G13: 0 | H13: 0 | I13: 0 | J13: 0 | K13: 1 | L13: 0 | M13: 1 | N13: 0 | O13: 0 | P13: 0 | Q13: 0 | R13: 0 | S13: 0 | T13: 0 | U13: 0 | V13: 0 | W13: 0 | X13: 0 | Y13: 0 | Z13: 1 | AA13: 1 | AB13: 0 | AC13: 0 | AD13: 1 | AE13: 0 | AF13: 1 | AG13: 0 | AH13: 1 | AI13: 0 | AJ13: 0 | AK13: 0 | AL13: 0 | AM13: 0 | AN13: 0 | AO13: 0 | AP13: 0 | AQ13: 0 | AR13: 0 | AS13: 1 | AT13: 0 | AU13: 0 | AV13: 0 | AW13: 0 | AX13: 0 | AY13: 0 | AZ13: 0 | BA13: 0 | BB13: 1 | BC13: 0 | BD13: 0 | BE13: 0 | BF13: 1 | BG13: 0 | BH13: 0 | BI13: 0 | BJ13: 0 | BK13: 0 | BL13: 1 | BM13: 0 | BN13: 1 | BO13: 1 | BP13: 1 | BQ13: 0 | BR13: 0 | BS13: 0 | BT13: 0 | BU13: 0 | BV13: 0 | BW13: 1 | BX13: 1 | BY13: 1 | BZ13: 0 | CA13: 1 | CB13: 0 | CC13: 0 | CD13: 0 | CE13: 0 | CF13: 0 | CG13: 1 | CH13: 0 | CI13: 1 | CJ13: 1 | CK13: 0 | CL13: 0 | CM13: 0 | CN13: 0 | CO13: 0 | CP13: 1 | CQ13: 1 | CR13: 1 | CS13: 1 | CT13: 0 | CU13: 0 | CV13: 1 | CW13: 0 | CX13: 0
A14: Earthquake-Manila | B14: 0.1 | C14: 0 | D14: 0 | E14: 0 | F14: 1 | G14: 0 | H14: 0 | I14: 0 | J14: 1 | K14: 0 | L14: 0 | M14: 0 | N14: 0 | O14: 0 | P14: 0 | Q14: 0 | R14: 0 | S14: 0 | T14: 0 | U14: 0 | V14: 1 | W14: 0 | X14: 0 | Y14: 0 | Z14: 0 | AA14: 0 | AB14: 0 | AC14: 0 | AD14: 0 | AE14: 1 | AF14: 0 | AG14: 0 | AH14: 0 | AI14: 0 | AJ14: 0 | AK14: 0 | AL14: 0 | AM14: 0 | AN14: 0 | AO14: 0 | AP14: 0 | AQ14: 0 | AR14: 0 | AS14: 0 | AT14: 0 | AU14: 0 | AV14: 0 | AW14: 0 | AX14: 0 | AY14: 0 | AZ14: 0 | BA14: 0 | BB14: 0 | BC14: 0 | BD14: 0 | BE14: 0 | BF14: 0 | BG14: 0 | BH14: 0 | BI14: 0 | BJ14: 0 | BK14: 0 | BL14: 0 | BM14: 0 | BN14: 0 | BO14: 0 | BP14: 1 | BQ14: 0 | BR14: 0 | BS14: 0 | BT14: 0 | BU14: 0 | BV14: 0 | BW14: 1 | BX14: 0 | BY14: 0 | BZ14: 1 | CA14: 0 | CB14: 0 | CC14: 1 | CD14: 0 | CE14: 1 | CF14: 0 | CG14: 0 | CH14: 1 | CI14: 0 | CJ14: 0 | CK14: 0 | CL14: 0 | CM14: 0 | CN14: 0 | CO14: 0 | CP14: 0 | CQ14: 0 | CR14: 0 | CS14: 0 | CT14: 0 | CU14: 0 | CV14: 0 | CW14: 0 | CX14: 0
A15: Fire-Manila | B15: 0.4 | C15: 0 | D15: 1 | E15: 0 | F15: 0 | G15: 0 | H15: 1 | I15: 0 | J15: 0 | K15: 1 | L15: 1 | M15: 0 | N15: 1 | O15: 0 | P15: 1 | Q15: 1 | R15: 0 | S15: 0 | T15: 1 | U15: 1 | V15: 1 | W15: 1 | X15: 0 | Y15: 0 | Z15: 0 | AA15: 0 | AB15: 1 | AC15: 1 | AD15: 1 | AE15: 0 | AF15: 1 | AG15: 1 | AH15: 0 | AI15: 0 | AJ15: 0 | AK15: 0 | AL15: 0 | AM15: 1 | AN15: 0 | AO15: 1 | AP15: 0 | AQ15: 0 | AR15: 1 | AS15: 0 | AT15: 1 | AU15: 0 | AV15: 0 | AW15: 1 | AX15: 1 | AY15: 0 | AZ15: 1 | BA15: 0 | BB15: 1 | BC15: 0 | BD15: 0 | BE15: 0 | BF15: 0 | BG15: 0 | BH15: 0 | BI15: 0 | BJ15: 0 | BK15: 1 | BL15: 1 | BM15: 0 | BN15: 1 | BO15: 0 | BP15: 1 | BQ15: 0 | BR15: 0 | BS15: 0 | BT15: 0 | BU15: 0 | BV15: 0 | BW15: 1 | BX15: 0 | BY15: 0 | BZ15: 0 | CA15: 1 | CB15: 0 | CC15: 0 | CD15: 0 | CE15: 0 | CF15: 1 | CG15: 0 | CH15: 0 | CI15: 1 | CJ15: 0 | CK15: 1 | CL15: 1 | CM15: 1 | CN15: 0 | CO15: 0 | CP15: 0 | CQ15: 1 | CR15: 1 | CS15: 1 | CT15: 0 | CU15: 0 | CV15: 0 | CW15: 0 | CX15: 0
A16: Thunderstorms, Tornados & Hail-San Francisco | B16: 0.18 | C16: 0 | D16: 0 | E16: 0 | F16: 0 | G16: 0 | H16: 0 | I16: 1 | J16: 0 | K16: 0 | L16: 0 | M16: 0 | N16: 0 | O16: 1 | P16: 0 | Q16: 0 | R16: 0 | S16: 0 | T16: 0 | U16: 0 | V16: 0 | W16: 0 | X16: 0 | Y16: 1 | Z16: 0 | AA16: 0 | AB16: 0 | AC16: 0 | AD16: 0 | AE16: 0 | AF16: 1 | AG16: 0 | AH16: 0 | AI16: 0 | AJ16: 0 | AK16: 0 | AL16: 0 | AM16: 0 | AN16: 0 | AO16: 0 | AP16: 0 | AQ16: 1 | AR16: 1 | AS16: 0 | AT16: 1 | AU16: 0 | AV16: 0 | AW16: 0 | AX16: 1 | AY16: 0 | AZ16: 0 | BA16: 0 | BB16: 0 | BC16: 0 | BD16: 0 | BE16: 0 | BF16: 0 | BG16: 1 | BH16: 0 | BI16: 1 | BJ16: 0 | BK16: 0 | BL16: 0 | BM16: 0 | BN16: 1 | BO16: 0 | BP16: 0 | BQ16: 0 | BR16: 0 | BS16: 0 | BT16: 0 | BU16: 0 | BV16: 0 | BW16: 0 | BX16: 1 | BY16: 0 | BZ16: 0 | CA16: 0 | CB16: 0 | CC16: 0 | CD16: 0 | CE16: 0 | CF16: 0 | CG16: 1 | CH16: 0 | CI16: 1 | CJ16: 0 | CK16: 0 | CL16: 1 | CM16: 1 | CN16: 0 | CO16: 0 | CP16: 0 | CQ16: 0 | CR16: 1 | CS16: 0 | CT16: 0 | CU16: 0 | CV16: 0 | CW16: 0 | CX16: 0
A17: Hurricane-Typhoon -San Francisco | B17: 0.26 | C17: 0 | D17: 1 | E17: 1 | F17: 1 | G17: 0 | H17: 0 | I17: 0 | J17: 0 | K17: 1 | L17: 0 | M17: 0 | N17: 1 | O17: 0 | P17: 1 | Q17: 0 | R17: 0 | S17: 1 | T17: 0 | U17: 0 | V17: 0 | W17: 1 | X17: 0 | Y17: 0 | Z17: 1 | AA17: 1 | AB17: 1 | AC17: 0 | AD17: 0 | AE17: 0 | AF17: 1 | AG17: 0 | AH17: 0 | AI17: 0 | AJ17: 0 | AK17: 0 | AL17: 1 | AM17: 1 | AN17: 0 | AO17: 1 | AP17: 0 | AQ17: 1 | AR17: 0 | AS17: 0 | AT17: 0 | AU17: 0 | AV17: 0 | AW17: 0 | AX17: 1 | AY17: 0 | AZ17: 0 | BA17: 0 | BB17: 0 | BC17: 1 | BD17: 0 | BE17: 0 | BF17: 0 | BG17: 0 | BH17: 0 | BI17: 0 | BJ17: 0 | BK17: 0 | BL17: 0 | BM17: 0 | BN17: 0 | BO17: 0 | BP17: 0 | BQ17: 0 | BR17: 0 | BS17: 0 | BT17: 0 | BU17: 1 | BV17: 0 | BW17: 0 | BX17: 0 | BY17: 0 | BZ17: 0 | CA17: 0 | CB17: 0 | CC17: 0 | CD17: 0 | CE17: 1 | CF17: 0 | CG17: 1 | CH17: 0 | CI17: 0 | CJ17: 0 | CK17: 0 | CL17: 0 | CM17: 0 | CN17: 1 | CO17: 0 | CP17: 0 | CQ17: 0 | CR17: 1 | CS17: 0 | CT17: 0 | CU17: 0 | CV17: 0 | CW17: 0 | CX17: 0
... A38: Hurricane-Typhoon -Texas | B38: 0.16 | C38: 0 | D38: 0 | E38: 0 | F38: 0 | G38: 1 | H38: 0 | I38: 0 | J38: 0 | K38: 0 | L38: 0 | M38: 0 | N38: 0 | O38: 0 | P38: 0 | Q38: 0 | R38: 0 | S38: 0 | T38: 0 | U38: 0 | V38: 0 | W38: 0 | X38: 0 | Y38: 0 | Z38: 0 | AA38: 1 | AB38: 0 | AC38: 0 | AD38: 0 | AE38: 1 | AF38: 1 | AG38: 0 | AH38: 0 | AI38: 0 | AJ38: 0 | AK38: 0 | AL38: 0 | AM38: 1 | AN38: 0 | AO38: 0 | AP38: 0 | AQ38: 0 | AR38: 0 | AS38: 0 | AT38: 0 | AU38: 0 | AV38: 0 | AW38: 0 | AX38: 0 | AY38: 1 | AZ38: 0 | BA38: 0 | BB38: 0 | BC38: 1 | BD38: 0 | BE38: 1 | BF38: 0 | BG38: 0 | BH38: 1 | BI38: 0 | BJ38: 0 | BK38: 0 | BL38: 0 | BM38: 0 | BN38: 0 | BO38: 0 | BP38: 0 | BQ38: 0 | BR38: 0 | BS38: 0 | BT38: 0 | BU38: 1 | BV38: 0 | BW38: 0 | BX38: 0 | BY38: 0 | BZ38: 0 | CA38: 0 | CB38: 0 | CC38: 0 | CD38: 0 | CE38: 0 | CF38: 0 | CG38: 0 | CH38: 0 | CI38: 0 | CJ38: 1 | CK38: 0 | CL38: 1 | CM38: 1 | CN38: 0 | CO38: 0 | CP38: 0 | CQ38: 0 | CR38: 1 | CS38: 0 | CT38: 1 | CU38: 0 | CV38: 1 | CW38: 0 | CX38: 1
C39: 7 | D39: 9 | E39: 9 | F39: 8 | G39: 3 | H39: 5 | I39: 5 | J39: 10 | K39: 9 | L39: 7 | M39: 10 | N39: 7 | O39: 6 | P39: 8 | Q39: 6 | R39: 2 | S39: 5 | T39: 9 | U39: 6 | V39: 9 | W39: 9 | X39: 6 | Y39: 7 | Z39: 12 | AA39: 9 | AB39: 7 | AC39: 8 | AD39: 9 | AE39: 3 | AF39: 10 | AG39: 6 | AH39: 8 | AI39: 5 | AJ39: 4 | AK39: 3 | AL39: 7 | AM39: 10 | AN39: 8 | AO39: 11 | AP39: 9 | AQ39: 8 | AR39: 12 | AS39: 4 | AT39: 7 | AU39: 4 | AV39: 7 | AW39: 7 | AX39: 14 | AY39: 5 | AZ39: 9 | BA39: 7 | BB39: 10 | BC39: 12 | BD39: 8 | BE39: 5 | BF39: 4 | BG39: 4 | BH39: 4 | BI39: 7 | BJ39: 6 | BK39: 4 | BL39: 9 | BM39: 5 | BN39: 11 | BO39: 9 | BP39: 9 | BQ39: 5 | BR39: 6 | BS39: 4 | BT39: 3 | BU39: 9 | BV39: 9 | BW39: 9 | BX39: 5 | BY39: 7 | BZ39: 7 | CA39: 7 | CB39: 5 | CC39: 4 | CD39: 8 | CE39: 7 | CF39: 7 | CG39: 8 | CH39: 7 | CI39: 6 | CJ39: 8 | CK39: 10 | CL39: 13 | CM39: 6 | CN39: 9 | CO39: 6 | CP39: 7 | CQ39: 6 | CR39: 9 | CS39: 8 | CT39: 8 | CU39: 8 | CV39: 8 | CW39: 8 | CX39: 6

Sheet Input Sheet year 1
A1: Policy Code | B1: Policy Desciption (Perils covered) | C1: Asset | D1: Asset Name | E1: Premium | H1: Policy Selection -Team 1 | I1: Policy Selection -Team 2 | J1: Policy Selection -Team 3 | K1: Policy Selection -Team 4 | L1: Policy Selection -Team 5 | M1: Policy Selection -Team 6 | N1: Policy Selection -Team 7 | O1: Policy Selection -Team 8 | P1: Policy Selection -Team 9 | Q1: Policy Selection -Team 10
H2: =IF(SUMIF(H3:H184,1,'Risk Master'!$N2)>H185,("Policy selection exceeded the budgeted amount by"& " " & SUMIF(H3:H184,1,'Risk Master'!$N2)-H185),SUMIF(H3:H184,1,'Risk Master'!$N2)) -> Policy selection exceeded the budgeted amount by 135000 | I2: =IF(SUMIF(I3:I184,1,'Risk Master'!$N2)>I185,("Policy selection exceeded the budgeted amount by"& " " & SUMIF(I3:I184,1,'Risk Master'!$N2)-I185),SUMIF(I3:I184,1,'Risk Master'!$N2)) -> 1430000 | J2: =IF(SUMIF(J3:J184,1,'Risk Master'!$N2)>J185,("Policy selection exceeded the budgeted amount by"& " " & SUMIF(J3:J184,1,'Risk Master'!$N2)-J185),SUMIF(J3:J184,1,'Risk Master'!$N2)) -> Policy selection exceeded the budgeted amount by 25000 | K2: =IF(SUMIF(K3:K184,1,'Risk Master'!$N2)>K185,("Policy selection exceeded the budgeted amount by"& " " & SUMIF(K3:K184,1,'Risk Master'!$N2)-K185),SUMIF(K3:K184,1,'Risk Master'!$N2)) -> 1510000 | L2: =IF(SUMIF(L3:L184,1,'Risk Master'!$N2)>L185,("Policy selection exceeded the budgeted amount by"& " " & SUMIF(L3:L184,1,'Risk Master'!$N2)-L185),SUMIF(L3:L184,1,'Risk Master'!$N2)) -> 1500000 | M2: =IF(SUMIF(M3:M184,1,'Risk Master'!$N2)>M185,("Policy selection exceeded the budgeted amount by"& " " & SUMIF(M3:M184,1,'Risk Master'!$N2)-M185),SUMIF(M3:M184,1,'Risk Master'!$N2)) -> 1390000 | N2: =IF(SUMIF(N3:N184,1,'Risk Master'!$N2)>N185,("Policy selection exceeded the budgeted amount by"& " " & SUMIF(N3:N184,1,'Risk Master'!$N2)-N185),SUMIF(N3:N184,1,'Risk Master'!$N2)) -> 1480000 | O2: =IF(SUMIF(O3:O184,1,'Risk Master'!$N2)>O185,("Policy selection exceeded the budgeted amount by"& " " & SUMIF(O3:O184,1,'Risk Master'!$N2)-O185),SUMIF(O3:O184,1,'Risk Master'!$N2)) -> 1480000 | ... Q2: =IF(SUMIF(Q3:Q184,1,'Risk Master'!$N2)>Q185,("Policy selection exceeded the budgeted amount by"& " " & SUMIF(Q3:Q184,1,'Risk Master'!$N2)-Q185),SUMIF(Q3:Q184,1,'Risk Master'!$N2)) -> Policy selection exceeded the budgeted amount by 15000
A3: P1 | B3: ='Risk Master'!C2&"-"&'Risk Master'!D2 -> Flood-Mumbai | C3: ='Risk Master'!F2 -> A1 | D3: =VLOOKUP(C3,'Asset Master'!A:B,2,FALSE) -> Heavy Machinery-Mumbai | E3: ='Risk Master'!N2 -> 20000 | H3: 0 | I3: 0 | J3: 0 | K3: 0 | L3: 0 | M3: 1 | N3: 1 | O3: 0 | P3: 1 | Q3: 1
A4: P2 | B4: ='Risk Master'!C3&"-"&'Risk Master'!D3 -> Earthquake-Mumbai | C4: ='Risk Master'!F3 -> A1 | D4: =VLOOKUP(C4,'Asset Master'!A:B,2,FALSE) -> Heavy Machinery-Mumbai | E4: ='Risk Master'!N3 -> 20000 | H4: 0 | I4: 1 | J4: 0 | K4: 0 | L4: 1 | M4: 1 | N4: 0 | O4: 0 | P4: 1 | Q4: 1
A5: P3 | B5: ='Risk Master'!C4&"-"&'Risk Master'!D4 -> Fire-Mumbai | C5: ='Risk Master'!F4 -> A1 | D5: =VLOOKUP(C5,'Asset Master'!A:B,2,FALSE) -> Heavy Machinery-Mumbai | E5: ='Risk Master'!N4 -> 20000 | H5: 0 | I5: 0 | J5: 0 | K5: 0 | L5: 0 | M5: 0 | N5: 0 | O5: 0 | P5: 0 | Q5: 0
A6: P4 | B6: ='Risk Master'!C5&"-"&'Risk Master'!D5 -> Typhoon-Mumbai | C6: ='Risk Master'!F5 -> A1 | D6: =VLOOKUP(C6,'Asset Master'!A:B,2,FALSE) -> Heavy Machinery-Mumbai | E6: ='Risk Master'!N5 -> 20000 | H6: 0 | I6: 0 | J6: 0 | K6: 1 | L6: 0 | M6: 1 | N6: 1 | O6: 0 | P6: 0 | Q6: 1
A7: P5 | B7: ='Risk Master'!C6&"-"&'Risk Master'!D6 -> Thunderstorms, Tornados & Hail-Mumbai | C7: ='Risk Master'!F6 -> A1 | D7: =VLOOKUP(C7,'Asset Master'!A:B,2,FALSE) -> Heavy Machinery-Mumbai | E7: ='Risk Master'!N6 -> 20000 | H7: 1 | I7: 0 | J7: 0 | K7: 0 | L7: 0 | M7: 0 | N7: 0 | O7: 0 | P7: 0 | Q7: 0
A8: P6 | B8: ='Risk Master'!C7&"-"&'Risk Master'!D7 -> Tsunami-Mumbai | C8: ='Risk Master'!F7 -> A1 | D8: =VLOOKUP(C8,'Asset Master'!A:B,2,FALSE) -> Heavy Machinery-Mumbai | E8: ='Risk Master'!N7 -> 20000 | H8: 0 | I8: 0 | J8: 0 | K8: 1 | L8: 0 | M8: 0 | N8: 0 | O8: 0 | P8: 0 | Q8: 0
A9: P7 | B9: ='Risk Master'!C8&"-"&'Risk Master'!D8 -> Flood-Mumbai | C9: ='Risk Master'!F8 -> A2 | D9: =VLOOKUP(C9,'Asset Master'!A:B,2,FALSE) -> Heat Exchanger-Mumbai | E9: ='Risk Master'!N8 -> 20000 | H9: 1 | I9: 0 | J9: 0 | K9: 0 | L9: 0 | M9: 1 | N9: 0 | O9: 0 | P9: 0 | Q9: 0
A10: P8 | B10: ='Risk Master'!C9&"-"&'Risk Master'!D9 -> Earthquake-Mumbai | C10: ='Risk Master'!F9 -> A2 | D10: =VLOOKUP(C10,'Asset Master'!A:B,2,FALSE) -> Heat Exchanger-Mumbai | E10: ='Risk Master'!N9 -> 20000 | H10: 0 | I10: 1 | J10: 0 | K10: 0 | L10: 0 | M10: 1 | N10: 0 | O10: 0 | P10: 0 | Q10: 0
A11: P9 | B11: ='Risk Master'!C10&"-"&'Risk Master'!D10 -> Fire-Mumbai | C11: ='Risk Master'!F10 -> A2 | D11: =VLOOKUP(C11,'Asset Master'!A:B,2,FALSE) -> Heat Exchanger-Mumbai | E11: ='Risk Master'!N10 -> 20000 | H11: 0 | I11: 0 | J11: 0 | K11: 0 | L11: 0 | M11: 1 | N11: 0 | O11: 0 | P11: 0 | Q11: 0
A12: P10 | B12: ='Risk Master'!C11&"-"&'Risk Master'!D11 -> Typhoon-Mumbai | C12: ='Risk Master'!F11 -> A2 | D12: =VLOOKUP(C12,'Asset Master'!A:B,2,FALSE) -> Heat Exchanger-Mumbai | E12: ='Risk Master'!N11 -> 20000 | H12: 1 | I12: 0 | J12: 0 | K12: 0 | L12: 0 | M12: 1 | N12: 0 | O12: 0 | P12: 1 | Q12: 0
A13: P11 | B13: ='Risk Master'!C12&"-"&'Risk Master'!D12 -> Thunderstorms, Tornados & Hail-Mumbai | C13: ='Risk Master'!F12 -> A4 | D13: =VLOOKUP(C13,'Asset Master'!A:B,2,FALSE) -> Property (Office Locations)-Mumbai | E13: ='Risk Master'!N12 -> 70000 | H13: 0 | I13: 0 | J13: 0 | K13: 0 | L13: 0 | M13: 0 | N13: 0 | O13: 0 | P13: 0 | Q13: 0
A14: P12 | B14: ='Risk Master'!C13&"-"&'Risk Master'!D13 -> Tsunami-Mumbai | C14: ='Risk Master'!F13 -> A4 | D14: =VLOOKUP(C14,'Asset Master'!A:B,2,FALSE) -> Property (Office Locations)-Mumbai | E14: ='Risk Master'!N13 -> 70000 | H14: 0 | I14: 0 | J14: 0 | K14: 0 | L14: 1 | M14: 0 | N14: 0 | O14: 0 | P14: 1 | Q14: 0
... A161: P159 | B161: ='Risk Master'!C160&"-"&'Risk Master'!D160 -> Thunderstorms, Tornados & Tropical storms-Caribbean Islands | C161: ='Risk Master'!F160 -> A113 | D161: =VLOOKUP(C161,'Asset Master'!A:B,2,FALSE) -> Supermarkets & Malls-Caribbean Islands | E161: ='Risk Master'!N160 -> 60000 | H161: 0 | I161: 0 | J161: 0 | K161: 0 | L161: 0 | M161: 0 | N161: 0 | O161: 1 | P161: 0 | Q161: 1
A162: P160 | B162: ='Risk Master'!C161&"-"&'Risk Master'!D161 -> Earthquake-Caribbean Islands | C162: ='Risk Master'!F161 -> A113 | D162: =VLOOKUP(C162,'Asset Master'!A:B,2,FALSE) -> Supermarkets & Malls-Caribbean Islands | E162: ='Risk Master'!N161 -> 60000 | H162: 0 | I162: 0 | J162: 1 | K162: 0 | L162: 0 | M162: 0 | N162: 1 | P162: 0 | Q162: 0
A163: P161 | B163: ='Risk Master'!C162&"-"&'Risk Master'!D162 -> Thunderstorms, Tornados & Hail-Caribbean Islands | C163: ='Risk Master'!F162 -> A113 | D163: =VLOOKUP(C163,'Asset Master'!A:B,2,FALSE) -> Supermarkets & Malls-Caribbean Islands | E163: ='Risk Master'!N162 -> 60000 | H163: 0 | I163: 1 | J163: 0 | K163: 0 | L163: 0 | M163: 0 | N163: 0 | O163: 0 | P163: 0 | Q163: 0
A164: P162 | B164: ='Risk Master'!C163&"-"&'Risk Master'!D163 -> Thunderstorms, Tornados & Tropical storms-Caribbean Islands | C164: ='Risk Master'!F163 -> A109 | D164: =VLOOKUP(C164,'Asset Master'!A:B,2,FALSE) -> Property (Office Locations)-Caribbean Islands | E164: ='Risk Master'!N163 -> 40000 | H164: 0 | I164: 0 | J164: 0 | K164: 0 | L164: 0 | M164: 0 | N164: 0 | O164: 0 | P164: 0 | Q164: 0
A165: P163 | B165: ='Risk Master'!C164&"-"&'Risk Master'!D164 -> Earthquake-Caribbean Islands | C165: ='Risk Master'!F164 -> A118 | D165: =VLOOKUP(C165,'Asset Master'!A:B,2,FALSE) -> Aircrafts-Caribbean Islands | E165: ='Risk Master'!N164 -> 60000 | H165: 0 | I165: 0 | J165: 0 | K165: 0 | L165: 1 | M165: 0 | N165: 0 | O165: 1 | P165: 0 | Q165: 0
A166: P164 | B166: ='Risk Master'!C165&"-"&'Risk Master'!D165 -> Hurricane-Typhoon -Caribbean Islands | C166: ='Risk Master'!F165 -> A118 | D166: =VLOOKUP(C166,'Asset Master'!A:B,2,FALSE) -> Aircrafts-Caribbean Islands | E166: ='Risk Master'!N165 -> 60000 | H166: 0 | I166: 0 | J166: 0 | K166: 0 | L166: 0 | M166: 0 | N166: 0 | O166: 0 | P166: 0 | Q166: 0
A167: P165 | B167: ='Risk Master'!C166&"-"&'Risk Master'!D166 -> Thunderstorms, Tornados & Hail-Caribbean Islands | C167: ='Risk Master'!F166 -> A118 | D167: =VLOOKUP(C167,'Asset Master'!A:B,2,FALSE) -> Aircrafts-Caribbean Islands | E167: ='Risk Master'!N166 -> 60000 | H167: 0 | I167: 0 | J167: 0 | K167: 0 | L167: 1 | M167: 0 | N167: 0 | O167: 0 | P167: 0 | Q167: 0
A168: P166 | B168: ='Risk Master'!C167&"-"&'Risk Master'!D167 -> Hurricane-Typhoon -Caribbean Islands | C168: ='Risk Master'!F167 -> A120 | D168: =VLOOKUP(C168,'Asset Master'!A:B,2,FALSE) -> Fleets & Cars-Caribbean Islands | E168: ='Risk Master'!N167 -> 20000 | H168: 0 | I168: 0 | J168: 0 | K168: 0 | L168: 0 | M168: 0 | N168: 0 | O168: 0 | P168: 0 | Q168: 0
A169: P167 | B169: ='Risk Master'!C168&"-"&'Risk Master'!D168 -> Earthquake-Caribbean Islands | C169: ='Risk Master'!F168 -> A120 | D169: =VLOOKUP(C169,'Asset Master'!A:B,2,FALSE) -> Fleets & Cars-Caribbean Islands | E169: ='Risk Master'!N168 -> 20000 | H169: 0 | I169: 0 | J169: 0 | K169: 0 | L169: 0 | M169: 0 | N169: 0 | O169: 0 | P169: 0 | Q169: 0
A170: P168 | B170: ='Risk Master'!C169&"-"&'Risk Master'!D169 -> Fire-Caribbean Islands | C170: ='Risk Master'!F169 -> A120 | D170: =VLOOKUP(C170,'Asset Master'!A:B,2,FALSE) -> Fleets & Cars-Caribbean Islands | E170: ='Risk Master'!N169 -> 20000 | H170: 0 | I170: 1 | J170: 1 | K170: 1 | L170: 1 | M170: 1 | N170: 1 | O170: 0 | P170: 0 | Q170: 0
A171: P169 | B171: ='Risk Master'!C170&"-"&'Risk Master'!D170 -> Tropical Storm-Caribbean Islands | C171: ='Risk Master'!F170 -> A120 | D171: =VLOOKUP(C171,'Asset Master'!A:B,2,FALSE) -> Fleets & Cars-Caribbean Islands | E171: ='Risk Master'!N170 -> 20000 | H171: 1 | I171: 0 | J171: 0 | K171: 0 | L171: 0 | M171: 0 | N171: 0 | O171: 0 | P171: 0 | Q171: 0
A172: P170 | B172: ='Risk Master'!C171&"-"&'Risk Master'!D171 -> Earthquake-Texas | C172: ='Risk Master'!F171 -> A124 | D172: =VLOOKUP(C172,'Asset Master'!A:B,2,FALSE) -> Property (Office Locations)-Texas | E172: ='Risk Master'!N171 -> 120000 | H172: 0 | I172: 0 | J172: 0 | K172: 0 | L172: 1 | M172: 0 | N172: 0 | O172: 0 | P172: 0 | Q172: 0
A173: P171 | B173: ='Risk Master'!C172&"-"&'Risk Master'!D172 -> Thunderstorms, Tornados & Hail-Texas | C173: ='Risk Master'!F172 -> A124 | D173: =VLOOKUP(C173,'Asset Master'!A:B,2,FALSE) -> Property (Office Locations)-Texas | E173: ='Risk Master'!N172 -> 120000 | H173: 1 | I173: 0 | J173: 1 | K173: 1 | L173: 0 | M173: 0 | N173: 0 | O173: 0 | P173: 0 | Q173: 0
A174: P172 | B174: ='Risk Master'!C173&"-"&'Risk Master'!D173 -> Hurricane-Typhoon -Texas | C174: ='Risk Master'!F173 -> A124 | D174: =VLOOKUP(C174,'Asset Master'!A:B,2,FALSE) -> Property (Office Locations)-Texas | E174: ='Risk Master'!N173 -> 120000 | H174: 0 | I174: 0 | J174: 0 | K174: 0 | L174: 0 | M174: 1 | N174: 1 | O174: 0 | P174: 0 | Q174: 0
... A184: P182 | B184: ='Risk Master'!C183&"-"&'Risk Master'!D183 -> Hurricane-Typhoon -Texas | C184: ='Risk Master'!F183 -> A135 | D184: =VLOOKUP(C184,'Asset Master'!A:B,2,FALSE) -> Fleets & Cars-Texas | E184: ='Risk Master'!N183 -> 20000 | H184: 0 | I184: 0 | J184: 0 | K184: 0 | L184: 0 | M184: 0 | N184: 1 | O184: 0 | P184: 0 | Q184: 0
E185: =SUM(E3:E184) -> 8190000 | H185: =0.05*'Asset Master'!$F$137 -> 1525000 | I185: =0.05*'Asset Master'!$F$137 -> 1525000 | J185: =0.05*'Asset Master'!$F$137 -> 1525000 | K185: =0.05*'Asset Master'!$F$137 -> 1525000 | L185: =0.05*'Asset Master'!$F$137 -> 1525000 | M185: =0.05*'Asset Master'!$F$137 -> 1525000 | N185: =0.05*'Asset Master'!$F$137 -> 1525000 | O185: =0.05*'Asset Master'!$F$137 -> 1525000 | ... Q185: =0.05*'Asset Master'!$F$137 -> 1525000

Sheet Year 1 Results
A1: Risk Event | B1: Peril | C1: Asset | D1: Results- Team 1 | E1: Results- Team 2 | F1: Results- Team 3 | G1: Results- Team 4 | H1: Results- Team 5 | I1: Results- Team 6 | J1: Results- Team 7 | K1: Results- Team 8 | L1: Results- Team 9 | M1: Results- Team 10 | O1: Year 1 Asset Value Team 1 | P1: Year 1 Asset Value Team 2 | Q1: Year 1 Asset Value Team 3 | R1: Year 1 Asset Value Team 4 | S1: Year 1 Asset Value Team 5 | T1: Year 1 Asset Value Team 6 | U1: Year 1 Asset Value Team 7 | V1: Year 1 Asset Value Team 8 | W1: Year 1 Asset Value Team 9 | X1: Year 1 Asset Value Team 10 | AA1: Result Team 1 | AB1: Result Team 2 | AC1: Result Team 3 | AD1: Result Team 4 | AE1: Result Team 5 | AF1: Result Team 6 | AG1: Result Team 7 | AH1: Result Team 8 | AI1: Result Team 9 | AJ1: Result Team 10
A2: ='Risk Master'!B2:B138&"-"&'Risk Master'!D2 -> High tide and high rainfalls leading to large floods-Mumbai | B2: ='Input Sheet year 2'!B3 -> Flood-Mumbai | C2: ='Risk Master'!F2 -> A1 | D2: ='Risk Master'!$G2*-1+('Risk Master'!$G2*'Event Trigger'!$D2*(1-'Input Sheet year 1'!H3)) -> 200000 | E2: ='Risk Master'!$G2*-1+('Risk Master'!$G2*'Event Trigger'!$D2*(1-'Input Sheet year 2'!I3)) -> 200000 | F2: ='Risk Master'!$G2*-1+('Risk Master'!$G2*'Event Trigger'!$D2*(1-'Input Sheet year 2'!J3)) -> 200000 | G2: ='Risk Master'!$G2*-1+('Risk Master'!$G2*'Event Trigger'!$D2*(1-'Input Sheet year 2'!K3)) -> 200000 | H2: ='Risk Master'!$G2*-1+('Risk Master'!$G2*'Event Trigger'!$D2*(1-'Input Sheet year 2'!L3)) -> 200000 | I2: ='Risk Master'!$G2*-1+('Risk Master'!$G2*'Event Trigger'!$D2*(1-'Input Sheet year 2'!M3)) -> 200000 | J2: ='Risk Master'!$G2*-1+('Risk Master'!$G2*'Event Trigger'!$D2*(1-'Input Sheet year 2'!N3)) -> 200000 | K2: ='Risk Master'!$G2*-1+('Risk Master'!$G2*'Event Trigger'!$D2*(1-'Input Sheet year 2'!O3)) -> 200000 | L2: ='Risk Master'!$G2*-1+('Risk Master'!$G2*'Event Trigger'!$D2*(1-'Input Sheet year 2'!P3)) -> 200000 | M2: ='Risk Master'!$G2*-1+('Risk Master'!$G2*'Event Trigger'!$D2*(1-'Input Sheet year 2'!Q3)) -> 200000 | O2: =VLOOKUP($C2,$Z:$AJ,2,FALSE)*-1 -> 0 | P2: =VLOOKUP($C2,$Z:$AJ,3,FALSE)*-1 -> 0 | Q2: =VLOOKUP($C2,$Z:$AJ,4,FALSE)*-1 -> 0 | R2: =VLOOKUP($C2,$Z:$AJ,5,FALSE)*-1 -> 0 | S2: =VLOOKUP($C2,$Z:$AJ,6,FALSE)*-1 -> 0 | T2: =VLOOKUP($C2,$Z:$AJ,7,FALSE)*-1 -> -200000 | U2: =VLOOKUP($C2,$Z:$AJ,8,FALSE)*-1 -> 0 | V2: =VLOOKUP($C2,$Z:$AJ,9,FALSE)*-1 -> 0 | W2: =VLOOKUP($C2,$Z:$AJ,10,FALSE)*-1 -> 0 | X2: =VLOOKUP($C2,$Z:$AJ,11,FALSE)*-1 -> -200000 | Z2: A1 | AA2: =IF(VLOOKUP($Z2,'Asset Master'!$A:$J,6,FALSE)*COUNTIF('Event Trigger'!$C:$C,'Year 1 Results'!$Z2)>SUMIF('Event Trigger'!$C:$C,$Z2,D:D),0,VLOOKUP($Z2,'Asset Master'!$A:$J,6,FALSE)) -> 0 | AB2: =IF(VLOOKUP($Z2,'Asset Master'!$A:$J,6,FALSE)*COUNTIF('Event Trigger'!$C:$C,'Year 1 Results'!$Z2)>SUMIF('Event Trigger'!$C:$C,$Z2,E:E),0,VLOOKUP($Z2,'Asset Master'!$A:$J,6,FALSE)) -> 0 | AC2: =IF(VLOOKUP($Z2,'Asset Master'!$A:$J,6,FALSE)*COUNTIF('Event Trigger'!$C:$C,'Year 1 Results'!$Z2)>SUMIF('Event Trigger'!$C:$C,$Z2,F:F),0,VLOOKUP($Z2,'Asset Master'!$A:$J,6,FALSE)) -> 0 | AD2: =IF(VLOOKUP($Z2,'Asset Master'!$A:$J,6,FALSE)*COUNTIF('Event Trigger'!$C:$C,'Year 1 Results'!$Z2)>SUMIF('Event Trigger'!$C:$C,$Z2,G:G),0,VLOOKUP($Z2,'Asset Master'!$A:$J,6,FALSE)) -> 0 | AE2: =IF(VLOOKUP($Z2,'Asset Master'!$A:$J,6,FALSE)*COUNTIF('Event Trigger'!$C:$C,'Year 1 Results'!$Z2)>SUMIF('Event Trigger'!$C:$C,$Z2,H:H),0,VLOOKUP($Z2,'Asset Master'!$A:$J,6,FALSE)) -> 0 | AF2: =IF(VLOOKUP($Z2,'Asset Master'!$A:$J,6,FALSE)*COUNTIF('Event Trigger'!$C:$C,'Year 1 Results'!$Z2)>SUMIF('Event Trigger'!$C:$C,$Z2,I:I),0,VLOOKUP($Z2,'Asset Master'!$A:$J,6,FALSE)) -> 200000 | AG2: =IF(VLOOKUP($Z2,'Asset Master'!$A:$J,6,FALSE)*COUNTIF('Event Trigger'!$C:$C,'Year 1 Results'!$Z2)>SUMIF('Event Trigger'!$C:$C,$Z2,J:J),0,VLOOKUP($Z2,'Asset Master'!$A:$J,6,FALSE)) -> 0 | AH2: =IF(VLOOKUP($Z2,'Asset Master'!$A:$J,6,FALSE)*COUNTIF('Event Trigger'!$C:$C,'Year 1 Results'!$Z2)>SUMIF('Event Trigger'!$C:$C,$Z2,K:K),0,VLOOKUP($Z2,'Asset Master'!$A:$J,6,FALSE)) -> 0 | AI2: =IF(VLOOKUP($Z2,'Asset Master'!$A:$J,6,FALSE)*COUNTIF('Event Trigger'!$C:$C,'Year 1 Results'!$Z2)>SUMIF('Event Trigger'!$C:$C,$Z2,L:L),0,VLOOKUP($Z2,'Asset Master'!$A:$J,6,FALSE)) -> 0 | AJ2: =IF(VLOOKUP($Z2,'Asset Master'!$A:$J,6,FALSE)*COUNTIF('Event Trigger'!$C:$C,'Year 1 Results'!$Z2)>SUMIF('Event Trigger'!$C:$C,$Z2,M:M),0,VLOOKUP($Z2,'Asset Master'!$A:$J,6,FALSE)) -> 200000
A3: ='Risk Master'!B3:B139&"-"&'Risk Master'!D3 -> Earthquake-Mumbai | B3: ='Input Sheet year 2'!B4 -> Earthquake-Mumbai | C3: ='Risk Master'!F3 -> A1 | D3: ='Risk Master'!$G3*-1+('Risk Master'!$G3*'Event Trigger'!$D3*(1-'Input Sheet year 1'!H4)) -> 0 | E3: ='Risk Master'!$G3*-1+('Risk Master'!$G3*'Event Trigger'!$D3*(1-'Input Sheet year 2'!I4)) -> 200000 | F3: ='Risk Master'!$G3*-1+('Risk Master'!$G3*'Event Trigger'!$D3*(1-'Input Sheet year 2'!J4)) -> 0 | G3: ='Risk Master'!$G3*-1+('Risk Master'!$G3*'Event Trigger'!$D3*(1-'Input Sheet year 2'!K4)) -> 0 | H3: ='Risk Master'!$G3*-1+('Risk Master'!$G3*'Event Trigger'!$D3*(1-'Input Sheet year 2'!L4)) -> 200000 | I3: ='Risk Master'!$G3*-1+('Risk Master'!$G3*'Event Trigger'!$D3*(1-'Input Sheet year 2'!M4)) -> 200000 | J3: ='Risk Master'!$G3*-1+('Risk Master'!$G3*'Event Trigger'!$D3*(1-'Input Sheet year 2'!N4)) -> 0 | K3: ='Risk Master'!$G3*-1+('Risk Master'!$G3*'Event Trigger'!$D3*(1-'Input Sheet year 2'!O4)) -> 0 | L3: ='Risk Master'!$G3*-1+('Risk Master'!$G3*'Event Trigger'!$D3*(1-'Input Sheet year 2'!P4)) -> 200000 | M3: ='Risk Master'!$G3*-1+('Risk Master'!$G3*'Event Trigger'!$D3*(1-'Input Sheet year 2'!Q4)) -> 200000 | O3: =VLOOKUP(C3,$Z:$AJ,2,FALSE)*-1 -> 0 | P3: =VLOOKUP($C3,$Z:$AJ,3,FALSE)*-1 -> 0 | Q3: =VLOOKUP($C3,$Z:$AJ,4,FALSE)*-1 -> 0 | R3: =VLOOKUP($C3,$Z:$AJ,5,FALSE)*-1 -> 0 | S3: =VLOOKUP($C3,$Z:$AJ,6,FALSE)*-1 -> 0 | T3: =VLOOKUP($C3,$Z:$AJ,7,FALSE)*-1 -> -200000 | U3: =VLOOKUP($C3,$Z:$AJ,8,FALSE)*-1 -> 0 | V3: =VLOOKUP($C3,$Z:$AJ,9,FALSE)*-1 -> 0 | W3: =VLOOKUP($C3,$Z:$AJ,10,FALSE)*-1 -> 0 | X3: =VLOOKUP($C3,$Z:$AJ,11,FALSE)*-1 -> -200000 | Z3: A2 | AA3: =IF(VLOOKUP($Z3,'Asset Master'!$A:$J,6,FALSE)*COUNTIF('Event Trigger'!$C:$C,'Year 1 Results'!$Z3)>SUMIF('Event Trigger'!$C:$C,$Z3,D:D),0,VLOOKUP($Z3,'Asset Master'!$A:$J,6,FALSE)) -> 0 | AB3: =IF(VLOOKUP($Z3,'Asset Master'!$A:$J,6,FALSE)*COUNTIF('Event Trigger'!$C:$C,'Year 1 Results'!$Z3)>SUMIF('Event Trigger'!$C:$C,$Z3,E:E),0,VLOOKUP($Z3,'Asset Master'!$A:$J,6,FALSE)) -> 0 | AC3: =IF(VLOOKUP($Z3,'Asset Master'!$A:$J,6,FALSE)*COUNTIF('Event Trigger'!$C:$C,'Year 1 Results'!$Z3)>SUMIF('Event Trigger'!$C:$C,$Z3,F:F),0,VLOOKUP($Z3,'Asset Master'!$A:$J,6,FALSE)) -> 0 | AD3: =IF(VLOOKUP($Z3,'Asset Master'!$A:$J,6,FALSE)*COUNTIF('Event Trigger'!$C:$C,'Year 1 Results'!$Z3)>SUMIF('Event Trigger'!$C:$C,$Z3,G:G),0,VLOOKUP($Z3,'Asset Master'!$A:$J,6,FALSE)) -> 0 | AE3: =IF(VLOOKUP($Z3,'Asset Master'!$A:$J,6,FALSE)*COUNTIF('Event Trigger'!$C:$C,'Year 1 Results'!$Z3)>SUMIF('Event Trigger'!$C:$C,$Z3,H:H),0,VLOOKUP($Z3,'Asset Master'!$A:$J,6,FALSE)) -> 0 | AF3: =IF(VLOOKUP($Z3,'Asset Master'!$A:$J,6,FALSE)*COUNTIF('Event Trigger'!$C:$C,'Year 1 Results'!$Z3)>SUMIF('Event Trigger'!$C:$C,$Z3,I:I),0,VLOOKUP($Z3,'Asset Master'!$A:$J,6,FALSE)) -> 200000 | AG3: =IF(VLOOKUP($Z3,'Asset Master'!$A:$J,6,FALSE)*COUNTIF('Event Trigger'!$C:$C,'Year 1 Results'!$Z3)>SUMIF('Event Trigger'!$C:$C,$Z3,J:J),0,VLOOKUP($Z3,'Asset Master'!$A:$J,6,FALSE)) -> 0 | AH3: =IF(VLOOKUP($Z3,'Asset Master'!$A:$J,6,FALSE)*COUNTIF('Event Trigger'!$C:$C,'Year 1 Results'!$Z3)>SUMIF('Event Trigger'!$C:$C,$Z3,K:K),0,VLOOKUP($Z3,'Asset Master'!$A:$J,6,FALSE)) -> 0 | AI3: =IF(VLOOKUP($Z3,'Asset Master'!$A:$J,6,FALSE)*COUNTIF('Event Trigger'!$C:$C,'Year 1 Results'!$Z3)>SUMIF('Event Trigger'!$C:$C,$Z3,L:L),0,VLOOKUP($Z3,'Asset Master'!$A:$J,6,FALSE)) -> 0 | AJ3: =IF(VLOOKUP($Z3,'Asset Master'!$A:$J,6,FALSE)*COUNTIF('Event Trigger'!$C:$C,'Year 1 Results'!$Z3)>SUMIF('Event Trigger'!$C:$C,$Z3,M:M),0,VLOOKUP($Z3,'Asset Master'!$A:$J,6,FALSE)) -> 0
A4: ='Risk Master'!B4:B140&"-"&'Risk Master'!D4 -> Fire-Mumbai | B4: ='Input Sheet year 2'!B5 -> Fire-Mumbai | C4: ='Risk Master'!F4 -> A1 | D4: ='Risk Master'!$G4*-1+('Risk Master'!$G4*'Event Trigger'!$D4*(1-'Input Sheet year 1'!H5)) -> 200000 | E4: ='Risk Master'!$G4*-1+('Risk Master'!$G4*'Event Trigger'!$D4*(1-'Input Sheet year 2'!I5)) -> 200000 | F4: ='Risk Master'!$G4*-1+('Risk Master'!$G4*'Event Trigger'!$D4*(1-'Input Sheet year 2'!J5)) -> 200000 | G4: ='Risk Master'!$G4*-1+('Risk Master'!$G4*'Event Trigger'!$D4*(1-'Input Sheet year 2'!K5)) -> 200000 | H4: ='Risk Master'!$G4*-1+('Risk Master'!$G4*'Event Trigger'!$D4*(1-'Input Sheet year 2'!L5)) -> 200000 | I4: ='Risk Master'!$G4*-1+('Risk Master'!$G4*'Event Trigger'!$D4*(1-'Input Sheet year 2'!M5)) -> 200000 | J4: ='Risk Master'!$G4*-1+('Risk Master'!$G4*'Event Trigger'!$D4*(1-'Input Sheet year 2'!N5)) -> 200000 | K4: ='Risk Master'!$G4*-1+('Risk Master'!$G4*'Event Trigger'!$D4*(1-'Input Sheet year 2'!O5)) -> 200000 | L4: ='Risk Master'!$G4*-1+('Risk Master'!$G4*'Event Trigger'!$D4*(1-'Input Sheet year 2'!P5)) -> 200000 | M4: ='Risk Master'!$G4*-1+('Risk Master'!$G4*'Event Trigger'!$D4*(1-'Input Sheet year 2'!Q5)) -> 200000 | O4: =VLOOKUP(C4,$Z:$AJ,2,FALSE)*-1 -> 0 | P4: =VLOOKUP($C4,$Z:$AJ,3,FALSE)*-1 -> 0 | Q4: =VLOOKUP($C4,$Z:$AJ,4,FALSE)*-1 -> 0 | R4: =VLOOKUP($C4,$Z:$AJ,5,FALSE)*-1 -> 0 | S4: =VLOOKUP($C4,$Z:$AJ,6,FALSE)*-1 -> 0 | T4: =VLOOKUP($C4,$Z:$AJ,7,FALSE)*-1 -> -200000 | U4: =VLOOKUP($C4,$Z:$AJ,8,FALSE)*-1 -> 0 | V4: =VLOOKUP($C4,$Z:$AJ,9,FALSE)*-1 -> 0 | W4: =VLOOKUP($C4,$Z:$AJ,10,FALSE)*-1 -> 0 | X4: =VLOOKUP($C4,$Z:$AJ,11,FALSE)*-1 -> -200000 | Z4: A3 | AA4: =IF(VLOOKUP($Z4,'Asset Master'!$A:$J,6,FALSE)*COUNTIF('Event Trigger'!$C:$C,'Year 1 Results'!$Z4)>SUMIF('Event Trigger'!$C:$C,$Z4,D:D),0,VLOOKUP($Z4,'Asset Master'!$A:$J,6,FALSE)) -> 0 | AB4: =IF(VLOOKUP($Z4,'Asset Master'!$A:$J,6,FALSE)*COUNTIF('Event Trigger'!$C:$C,'Year 1 Results'!$Z4)>SUMIF('Event Trigger'!$C:$C,$Z4,E:E),0,VLOOKUP($Z4,'Asset Master'!$A:$J,6,FALSE)) -> 0 | AC4: =IF(VLOOKUP($Z4,'Asset Master'!$A:$J,6,FALSE)*COUNTIF('Event Trigger'!$C:$C,'Year 1 Results'!$Z4)>SUMIF('Event Trigger'!$C:$C,$Z4,F:F),0,VLOOKUP($Z4,'Asset Master'!$A:$J,6,FALSE)) -> 0 | AD4: =IF(VLOOKUP($Z4,'Asset Master'!$A:$J,6,FALSE)*COUNTIF('Event Trigger'!$C:$C,'Year 1 Results'!$Z4)>SUMIF('Event Trigger'!$C:$C,$Z4,G:G),0,VLOOKUP($Z4,'Asset Master'!$A:$J,6,FALSE)) -> 0 | AE4: =IF(VLOOKUP($Z4,'Asset Master'!$A:$J,6,FALSE)*COUNTIF('Event Trigger'!$C:$C,'Year 1 Results'!$Z4)>SUMIF('Event Trigger'!$C:$C,$Z4,H:H),0,VLOOKUP($Z4,'Asset Master'!$A:$J,6,FALSE)) -> 0 | AF4: =IF(VLOOKUP($Z4,'Asset Master'!$A:$J,6,FALSE)*COUNTIF('Event Trigger'!$C:$C,'Year 1 Results'!$Z4)>SUMIF('Event Trigger'!$C:$C,$Z4,I:I),0,VLOOKUP($Z4,'Asset Master'!$A:$J,6,FALSE)) -> 0 | AG4: =IF(VLOOKUP($Z4,'Asset Master'!$A:$J,6,FALSE)*COUNTIF('Event Trigger'!$C:$C,'Year 1 Results'!$Z4)>SUMIF('Event Trigger'!$C:$C,$Z4,J:J),0,VLOOKUP($Z4,'Asset Master'!$A:$J,6,FALSE)) -> 0 | AH4: =IF(VLOOKUP($Z4,'Asset Master'!$A:$J,6,FALSE)*COUNTIF('Event Trigger'!$C:$C,'Year 1 Results'!$Z4)>SUMIF('Event Trigger'!$C:$C,$Z4,K:K),0,VLOOKUP($Z4,'Asset Master'!$A:$J,6,FALSE)) -> 0 | AI4: =IF(VLOOKUP($Z4,'Asset Master'!$A:$J,6,FALSE)*COUNTIF('Event Trigger'!$C:$C,'Year 1 Results'!$Z4)>SUMIF('Event Trigger'!$C:$C,$Z4,L:L),0,VLOOKUP($Z4,'Asset Master'!$A:$J,6,FALSE)) -> 0 | AJ4: =IF(VLOOKUP($Z4,'Asset Master'!$A:$J,6,FALSE)*COUNTIF('Event Trigger'!$C:$C,'Year 1 Results'!$Z4)>SUMIF('Event Trigger'!$C:$C,$Z4,M:M),0,VLOOKUP($Z4,'Asset Master'!$A:$J,6,FALSE)) -> 0
A5: ='Risk Master'!B5:B141&"-"&'Risk Master'!D5 -> Typhoon-Mumbai | B5: ='Input Sheet year 2'!B6 -> Typhoon-Mumbai | C5: ='Risk Master'!F5 -> A1 | D5: ='Risk Master'!$G5*-1+('Risk Master'!$G5*'Event Trigger'!$D5*(1-'Input Sheet year 1'!H6)) -> 0 | E5: ='Risk Master'!$G5*-1+('Risk Master'!$G5*'Event Trigger'!$D5*(1-'Input Sheet year 2'!I6)) -> 0 | F5: ='Risk Master'!$G5*-1+('Risk Master'!$G5*'Event Trigger'!$D5*(1-'Input Sheet year 2'!J6)) -> 0 | G5: ='Risk Master'!$G5*-1+('Risk Master'!$G5*'Event Trigger'!$D5*(1-'Input Sheet year 2'!K6)) -> 200000 | H5: ='Risk Master'!$G5*-1+('Risk Master'!$G5*'Event Trigger'!$D5*(1-'Input Sheet year 2'!L6)) -> 0 | I5: ='Risk Master'!$G5*-1+('Risk Master'!$G5*'Event Trigger'!$D5*(1-'Input Sheet year 2'!M6)) -> 200000 | J5: ='Risk Master'!$G5*-1+('Risk Master'!$G5*'Event Trigger'!$D5*(1-'Input Sheet year 2'!N6)) -> 200000 | K5: ='Risk Master'!$G5*-1+('Risk Master'!$G5*'Event Trigger'!$D5*(1-'Input Sheet year 2'!O6)) -> 0 | L5: ='Risk Master'!$G5*-1+('Risk Master'!$G5*'Event Trigger'!$D5*(1-'Input Sheet year 2'!P6)) -> 0 | M5: ='Risk Master'!$G5*-1+('Risk Master'!$G5*'Event Trigger'!$D5*(1-'Input Sheet year 2'!Q6)) -> 200000 | O5: =VLOOKUP(C5,$Z:$AJ,2,FALSE)*-1 -> 0 | P5: =VLOOKUP($C5,$Z:$AJ,3,FALSE)*-1 -> 0 | Q5: =VLOOKUP($C5,$Z:$AJ,4,FALSE)*-1 -> 0 | R5: =VLOOKUP($C5,$Z:$AJ,5,FALSE)*-1 -> 0 | S5: =VLOOKUP($C5,$Z:$AJ,6,FALSE)*-1 -> 0 | T5: =VLOOKUP($C5,$Z:$AJ,7,FALSE)*-1 -> -200000 | U5: =VLOOKUP($C5,$Z:$AJ,8,FALSE)*-1 -> 0 | V5: =VLOOKUP($C5,$Z:$AJ,9,FALSE)*-1 -> 0 | W5: =VLOOKUP($C5,$Z:$AJ,10,FALSE)*-1 -> 0 | X5: =VLOOKUP($C5,$Z:$AJ,11,FALSE)*-1 -> -200000 | Z5: A4 | AA5: =IF(VLOOKUP($Z5,'Asset Master'!$A:$J,6,FALSE)*COUNTIF('Event Trigger'!$C:$C,'Year 1 Results'!$Z5)>SUMIF('Event Trigger'!$C:$C,$Z5,D:D),0,VLOOKUP($Z5,'Asset Master'!$A:$J,6,FALSE)) -> 700000 | AB5: =IF(VLOOKUP($Z5,'Asset Master'!$A:$J,6,FALSE)*COUNTIF('Event Trigger'!$C:$C,'Year 1 Results'!$Z5)>SUMIF('Event Trigger'!$C:$C,$Z5,E:E),0,VLOOKUP($Z5,'Asset Master'!$A:$J,6,FALSE)) -> 700000 | AC5: =IF(VLOOKUP($Z5,'Asset Master'!$A:$J,6,FALSE)*COUNTIF('Event Trigger'!$C:$C,'Year 1 Results'!$Z5)>SUMIF('Event Trigger'!$C:$C,$Z5,F:F),0,VLOOKUP($Z5,'Asset Master'!$A:$J,6,FALSE)) -> 700000 | AD5: =IF(VLOOKUP($Z5,'Asset Master'!$A:$J,6,FALSE)*COUNTIF('Event Trigger'!$C:$C,'Year 1 Results'!$Z5)>SUMIF('Event Trigger'!$C:$C,$Z5,G:G),0,VLOOKUP($Z5,'Asset Master'!$A:$J,6,FALSE)) -> 700000 | AE5: =IF(VLOOKUP($Z5,'Asset Master'!$A:$J,6,FALSE)*COUNTIF('Event Trigger'!$C:$C,'Year 1 Results'!$Z5)>SUMIF('Event Trigger'!$C:$C,$Z5,H:H),0,VLOOKUP($Z5,'Asset Master'!$A:$J,6,FALSE)) -> 700000 | AF5: =IF(VLOOKUP($Z5,'Asset Master'!$A:$J,6,FALSE)*COUNTIF('Event Trigger'!$C:$C,'Year 1 Results'!$Z5)>SUMIF('Event Trigger'!$C:$C,$Z5,I:I),0,VLOOKUP($Z5,'Asset Master'!$A:$J,6,FALSE)) -> 700000 | AG5: =IF(VLOOKUP($Z5,'Asset Master'!$A:$J,6,FALSE)*COUNTIF('Event Trigger'!$C:$C,'Year 1 Results'!$Z5)>SUMIF('Event Trigger'!$C:$C,$Z5,J:J),0,VLOOKUP($Z5,'Asset Master'!$A:$J,6,FALSE)) -> 700000 | AH5: =IF(VLOOKUP($Z5,'Asset Master'!$A:$J,6,FALSE)*COUNTIF('Event Trigger'!$C:$C,'Year 1 Results'!$Z5)>SUMIF('Event Trigger'!$C:$C,$Z5,K:K),0,VLOOKUP($Z5,'Asset Master'!$A:$J,6,FALSE)) -> 700000 | AI5: =IF(VLOOKUP($Z5,'Asset Master'!$A:$J,6,FALSE)*COUNTIF('Event Trigger'!$C:$C,'Year 1 Results'!$Z5)>SUMIF('Event Trigger'!$C:$C,$Z5,L:L),0,VLOOKUP($Z5,'Asset Master'!$A:$J,6,FALSE)) -> 700000 | AJ5: =IF(VLOOKUP($Z5,'Asset Master'!$A:$J,6,FALSE)*COUNTIF('Event Trigger'!$C:$C,'Year 1 Results'!$Z5)>SUMIF('Event Trigger'!$C:$C,$Z5,M:M),0,VLOOKUP($Z5,'Asset Master'!$A:$J,6,FALSE)) -> 700000
A6: ='Risk Master'!B6:B142&"-"&'Risk Master'!D6 -> Thunderstorms, Tornados & Hail-Mumbai | B6: ='Input Sheet year 2'!B7 -> Thunderstorms, Tornados & Hail-Mumbai | C6: ='Risk Master'!F6 -> A1 | D6: ='Risk Master'!$G6*-1+('Risk Master'!$G6*'Event Trigger'!$D6*(1-'Input Sheet year 1'!H7)) -> 200000 | E6: ='Risk Master'!$G6*-1+('Risk Master'!$G6*'Event Trigger'!$D6*(1-'Input Sheet year 2'!I7)) -> 200000 | F6: ='Risk Master'!$G6*-1+('Risk Master'!$G6*'Event Trigger'!$D6*(1-'Input Sheet year 2'!J7)) -> 200000 | G6: ='Risk Master'!$G6*-1+('Risk Master'!$G6*'Event Trigger'!$D6*(1-'Input Sheet year 2'!K7)) -> 200000 | H6: ='Risk Master'!$G6*-1+('Risk Master'!$G6*'Event Trigger'!$D6*(1-'Input Sheet year 2'!L7)) -> 200000 | I6: ='Risk Master'!$G6*-1+('Risk Master'!$G6*'Event Trigger'!$D6*(1-'Input Sheet year 2'!M7)) -> 200000 | J6: ='Risk Master'!$G6*-1+('Risk Master'!$G6*'Event Trigger'!$D6*(1-'Input Sheet year 2'!N7)) -> 200000 | K6: ='Risk Master'!$G6*-1+('Risk Master'!$G6*'Event Trigger'!$D6*(1-'Input Sheet year 2'!O7)) -> 200000 | L6: ='Risk Master'!$G6*-1+('Risk Master'!$G6*'Event Trigger'!$D6*(1-'Input Sheet year 2'!P7)) -> 200000 | M6: ='Risk Master'!$G6*-1+('Risk Master'!$G6*'Event Trigger'!$D6*(1-'Input Sheet year 2'!Q7)) -> 200000 | O6: =VLOOKUP(C6,$Z:$AJ,2,FALSE)*-1 -> 0 | P6: =VLOOKUP($C6,$Z:$AJ,3,FALSE)*-1 -> 0 | Q6: =VLOOKUP($C6,$Z:$AJ,4,FALSE)*-1 -> 0 | R6: =VLOOKUP($C6,$Z:$AJ,5,FALSE)*-1 -> 0 | S6: =VLOOKUP($C6,$Z:$AJ,6,FALSE)*-1 -> 0 | T6: =VLOOKUP($C6,$Z:$AJ,7,FALSE)*-1 -> -200000 | U6: =VLOOKUP($C6,$Z:$AJ,8,FALSE)*-1 -> 0 | V6: =VLOOKUP($C6,$Z:$AJ,9,FALSE)*-1 -> 0 | W6: =VLOOKUP($C6,$Z:$AJ,10,FALSE)*-1 -> 0 | X6: =VLOOKUP($C6,$Z:$AJ,11,FALSE)*-1 -> -200000 | Z6: A5 | AA6: =IF(VLOOKUP($Z6,'Asset Master'!$A:$J,6,FALSE)*COUNTIF('Event Trigger'!$C:$C,'Year 1 Results'!$Z6)>SUMIF('Event Trigger'!$C:$C,$Z6,D:D),0,VLOOKUP($Z6,'Asset Master'!$A:$J,6,FALSE)) -> 0 | AB6: =IF(VLOOKUP($Z6,'Asset Master'!$A:$J,6,FALSE)*COUNTIF('Event Trigger'!$C:$C,'Year 1 Results'!$Z6)>SUMIF('Event Trigger'!$C:$C,$Z6,E:E),0,VLOOKUP($Z6,'Asset Master'!$A:$J,6,FALSE)) -> 0 | AC6: =IF(VLOOKUP($Z6,'Asset Master'!$A:$J,6,FALSE)*COUNTIF('Event Trigger'!$C:$C,'Year 1 Results'!$Z6)>SUMIF('Event Trigger'!$C:$C,$Z6,F:F),0,VLOOKUP($Z6,'Asset Master'!$A:$J,6,FALSE)) -> 0 | AD6: =IF(VLOOKUP($Z6,'Asset Master'!$A:$J,6,FALSE)*COUNTIF('Event Trigger'!$C:$C,'Year 1 Results'!$Z6)>SUMIF('Event Trigger'!$C:$C,$Z6,G:G),0,VLOOKUP($Z6,'Asset Master'!$A:$J,6,FALSE)) -> 0 | AE6: =IF(VLOOKUP($Z6,'Asset Master'!$A:$J,6,FALSE)*COUNTIF('Event Trigger'!$C:$C,'Year 1 Results'!$Z6)>SUMIF('Event Trigger'!$C:$C,$Z6,H:H),0,VLOOKUP($Z6,'Asset Master'!$A:$J,6,FALSE)) -> 0 | AF6: =IF(VLOOKUP($Z6,'Asset Master'!$A:$J,6,FALSE)*COUNTIF('Event Trigger'!$C:$C,'Year 1 Results'!$Z6)>SUMIF('Event Trigger'!$C:$C,$Z6,I:I),0,VLOOKUP($Z6,'Asset Master'!$A:$J,6,FALSE)) -> 0 | AG6: =IF(VLOOKUP($Z6,'Asset Master'!$A:$J,6,FALSE)*COUNTIF('Event Trigger'!$C:$C,'Year 1 Results'!$Z6)>SUMIF('Event Trigger'!$C:$C,$Z6,J:J),0,VLOOKUP($Z6,'Asset Master'!$A:$J,6,FALSE)) -> 0 | AH6: =IF(VLOOKUP($Z6,'Asset Master'!$A:$J,6,FALSE)*COUNTIF('Event Trigger'!$C:$C,'Year 1 Results'!$Z6)>SUMIF('Event Trigger'!$C:$C,$Z6,K:K),0,VLOOKUP($Z6,'Asset Master'!$A:$J,6,FALSE)) -> 0 | AI6: =IF(VLOOKUP($Z6,'Asset Master'!$A:$J,6,FALSE)*COUNTIF('Event Trigger'!$C:$C,'Year 1 Results'!$Z6)>SUMIF('Event Trigger'!$C:$C,$Z6,L:L),0,VLOOKUP($Z6,'Asset Master'!$A:$J,6,FALSE)) -> 0 | AJ6: =IF(VLOOKUP($Z6,'Asset Master'!$A:$J,6,FALSE)*COUNTIF('Event Trigger'!$C:$C,'Year 1 Results'!$Z6)>SUMIF('Event Trigger'!$C:$C,$Z6,M:M),0,VLOOKUP($Z6,'Asset Master'!$A:$J,6,FALSE)) -> 0
A7: ='Risk Master'!B7:B143&"-"&'Risk Master'!D7 -> Tsunami-Mumbai | B7: ='Input Sheet year 2'!B8 -> Tsunami-Mumbai | C7: ='Risk Master'!F7 -> A1 | D7: ='Risk Master'!$G7*-1+('Risk Master'!$G7*'Event Trigger'!$D7*(1-'Input Sheet year 1'!H8)) -> 200000 | E7: ='Risk Master'!$G7*-1+('Risk Master'!$G7*'Event Trigger'!$D7*(1-'Input Sheet year 2'!I8)) -> 200000 | F7: ='Risk Master'!$G7*-1+('Risk Master'!$G7*'Event Trigger'!$D7*(1-'Input Sheet year 2'!J8)) -> 200000 | G7: ='Risk Master'!$G7*-1+('Risk Master'!$G7*'Event Trigger'!$D7*(1-'Input Sheet year 2'!K8)) -> 200000 | H7: ='Risk Master'!$G7*-1+('Risk Master'!$G7*'Event Trigger'!$D7*(1-'Input Sheet year 2'!L8)) -> 200000 | I7: ='Risk Master'!$G7*-1+('Risk Master'!$G7*'Event Trigger'!$D7*(1-'Input Sheet year 2'!M8)) -> 200000 | J7: ='Risk Master'!$G7*-1+('Risk Master'!$G7*'Event Trigger'!$D7*(1-'Input Sheet year 2'!N8)) -> 200000 | K7: ='Risk Master'!$G7*-1+('Risk Master'!$G7*'Event Trigger'!$D7*(1-'Input Sheet year 2'!O8)) -> 200000 | L7: ='Risk Master'!$G7*-1+('Risk Master'!$G7*'Event Trigger'!$D7*(1-'Input Sheet year 2'!P8)) -> 200000 | M7: ='Risk Master'!$G7*-1+('Risk Master'!$G7*'Event Trigger'!$D7*(1-'Input Sheet year 2'!Q8)) -> 200000 | O7: =VLOOKUP(C7,$Z:$AJ,2,FALSE)*-1 -> 0 | P7: =VLOOKUP($C7,$Z:$AJ,3,FALSE)*-1 -> 0 | Q7: =VLOOKUP($C7,$Z:$AJ,4,FALSE)*-1 -> 0 | R7: =VLOOKUP($C7,$Z:$AJ,5,FALSE)*-1 -> 0 | S7: =VLOOKUP($C7,$Z:$AJ,6,FALSE)*-1 -> 0 | T7: =VLOOKUP($C7,$Z:$AJ,7,FALSE)*-1 -> -200000 | U7: =VLOOKUP($C7,$Z:$AJ,8,FALSE)*-1 -> 0 | V7: =VLOOKUP($C7,$Z:$AJ,9,FALSE)*-1 -> 0 | W7: =VLOOKUP($C7,$Z:$AJ,10,FALSE)*-1 -> 0 | X7: =VLOOKUP($C7,$Z:$AJ,11,FALSE)*-1 -> -200000 | Z7: A6 | AA7: =IF(VLOOKUP($Z7,'Asset Master'!$A:$J,6,FALSE)*COUNTIF('Event Trigger'!$C:$C,'Year 1 Results'!$Z7)>SUMIF('Event Trigger'!$C:$C,$Z7,D:D),0,VLOOKUP($Z7,'Asset Master'!$A:$J,6,FALSE)) -> 400000 | AB7: =IF(VLOOKUP($Z7,'Asset Master'!$A:$J,6,FALSE)*COUNTIF('Event Trigger'!$C:$C,'Year 1 Results'!$Z7)>SUMIF('Event Trigger'!$C:$C,$Z7,E:E),0,VLOOKUP($Z7,'Asset Master'!$A:$J,6,FALSE)) -> 0 | AC7: =IF(VLOOKUP($Z7,'Asset Master'!$A:$J,6,FALSE)*COUNTIF('Event Trigger'!$C:$C,'Year 1 Results'!$Z7)>SUMIF('Event Trigger'!$C:$C,$Z7,F:F),0,VLOOKUP($Z7,'Asset Master'!$A:$J,6,FALSE)) -> 0 | AD7: =IF(VLOOKUP($Z7,'Asset Master'!$A:$J,6,FALSE)*COUNTIF('Event Trigger'!$C:$C,'Year 1 Results'!$Z7)>SUMIF('Event Trigger'!$C:$C,$Z7,G:G),0,VLOOKUP($Z7,'Asset Master'!$A:$J,6,FALSE)) -> 0 | AE7: =IF(VLOOKUP($Z7,'Asset Master'!$A:$J,6,FALSE)*COUNTIF('Event Trigger'!$C:$C,'Year 1 Results'!$Z7)>SUMIF('Event Trigger'!$C:$C,$Z7,H:H),0,VLOOKUP($Z7,'Asset Master'!$A:$J,6,FALSE)) -> 0 | AF7: =IF(VLOOKUP($Z7,'Asset Master'!$A:$J,6,FALSE)*COUNTIF('Event Trigger'!$C:$C,'Year 1 Results'!$Z7)>SUMIF('Event Trigger'!$C:$C,$Z7,I:I),0,VLOOKUP($Z7,'Asset Master'!$A:$J,6,FALSE)) -> 0 | AG7: =IF(VLOOKUP($Z7,'Asset Master'!$A:$J,6,FALSE)*COUNTIF('Event Trigger'!$C:$C,'Year 1 Results'!$Z7)>SUMIF('Event Trigger'!$C:$C,$Z7,J:J),0,VLOOKUP($Z7,'Asset Master'!$A:$J,6,FALSE)) -> 0 | AH7: =IF(VLOOKUP($Z7,'Asset Master'!$A:$J,6,FALSE)*COUNTIF('Event Trigger'!$C:$C,'Year 1 Results'!$Z7)>SUMIF('Event Trigger'!$C:$C,$Z7,K:K),0,VLOOKUP($Z7,'Asset Master'!$A:$J,6,FALSE)) -> 0 | AI7: =IF(VLOOKUP($Z7,'Asset Master'!$A:$J,6,FALSE)*COUNTIF('Event Trigger'!$C:$C,'Year 1 Results'!$Z7)>SUMIF('Event Trigger'!$C:$C,$Z7,L:L),0,VLOOKUP($Z7,'Asset Master'!$A:$J,6,FALSE)) -> 0 | AJ7: =IF(VLOOKUP($Z7,'Asset Master'!$A:$J,6,FALSE)*COUNTIF('Event Trigger'!$C:$C,'Year 1 Results'!$Z7)>SUMIF('Event Trigger'!$C:$C,$Z7,M:M),0,VLOOKUP($Z7,'Asset Master'!$A:$J,6,FALSE)) -> 0
